2021-01-03 11:08:32,026 - WARNING - We are being rate limited. Retrying in 0.09 seconds. Handled under the bucket "696320172419448842:None:/channels/{channel_id}/messages/{message_id}/reactions/{emoji}/@me"
2021-01-03 11:08:48,007 - WARNING - We are being rate limited. Retrying in 0.10 seconds. Handled under the bucket "696320146486198362:None:/channels/{channel_id}/messages/{message_id}/reactions/{emoji}/@me"
2021-01-03 11:08:59,040 - WARNING - We are being rate limited. Retrying in 0.09 seconds. Handled under the bucket "696314429066969099:None:/channels/{channel_id}/messages/{message_id}/reactions/{emoji}/@me"
2021-01-03 11:09:05,261 - WARNING - We are being rate limited. Retrying in 0.09 seconds. Handled under the bucket "696346675223986236:None:/channels/{channel_id}/messages/{message_id}/reactions/{emoji}/@me"
2021-01-03 12:18:09,947 - WARNING - We are being rate limited. Retrying in 0.09 seconds. Handled under the bucket "697889935285289000:None:/channels/{channel_id}/messages/{message_id}/reactions/{emoji}/@me"
Ignoring exception in command None:
discord.ext.commands.errors.CommandNotFound: Command "&unmute" is not found
Vérification de la base de donnée...

Suppression de la commande help...
Effectué!

Génération des modules logs...
logs/messageEdit.py
Lancement du module messageEdit
logs/voiceConnection.py
Lancement du module voiceConnection
logs/guildChannelCreate.py
Lancement du module guildChannelCreate
logs/guildMemberJoin.py
Lancement du module guildMemberJoin
logs/guildRoleDelete.py
Lancement du module guildRoleDelete
logs/guildChannelDelete.py
Lancement du module guildChannelDelete
logs/messageAddReaction.py
Lancement du module messageAddReaction
logs/guildUserUpdate.py
Lancement du module guildUserUpdate
logs/voiceUpdate.py
Lancement du module voiceUpdate
logs/voiceSelfUpdate.py
Lancement du module voiceSelfUpdate
logs/messageRemoveReaction.py
Lancement du module messageRemoveReaction
logs/messageCreate.py
Lancement du module messageCreate
logs/guildRoleCreate.py
Lancement du module guildRoleCreate
logs/guildMemberLeave.py
Lancement du module guildMemberLeave
logs/messageDelete.py
Lancement du module messageDelete
logs/voiceSwitch.py
Lancement du module voiceSwitch
logs/guildMemberUpdate.py
Lancement du module guildMemberUpdate

Génération des modules commandes...
Lancement du module help_command
Lancement du module administration
Lancement du module moderation

Lancement du bot...
UMMBOT est prêt!
Lien d'invitation: https://discord.com/oauth2/authorize?client_id=677213520529457152&scope=bot&permissions=8

Pour inviter UMMBot, veillez copier ce lien et mettre au bot la permission administrateur.
Une fois rejoint, veillez déplacer le rôle UMMBot tout en haut de la liste des rôles.
En cas de problème, veillez contacter Bretzel_#2246.
New guild ! 672867622731251739
Guild (672867622731251739) db created
messageDelete.py -> Bot delete
messageDelete.py -> Bot delete
messageDelete.py -> Bot delete
messageDelete.py -> Bot delete
messageDelete.py -> Bot delete
messageDelete.py -> Bot delete
messageDelete.py -> Bot delete
messageDelete.py -> Bot delete
messageDelete.py -> Bot delete
messageDelete.py -> Bot delete
messageDelete.py -> Bot delete
messageDelete.py -> Bot delete
messageDelete.py -> Bot delete
messageDelete.py -> Bot delete
messageDelete.py -> Bot delete
messageDelete.py -> Bot delete
Ignoring exception in command None:
discord.ext.commands.errors.CommandNotFound: Command "&automod" is not found
2021-01-03 12:30:08,883 - WARNING - We are being rate limited. Retrying in 0.01 seconds. Handled under the bucket "697889935285289000:None:/channels/{channel_id}/messages/{message_id}/reactions/{emoji}/@me"
2021-01-03 12:30:19,727 - WARNING - We are being rate limited. Retrying in 0.10 seconds. Handled under the bucket "697889935285289000:None:/channels/{channel_id}/messages/{message_id}/reactions/{emoji}/@me"
2021-01-03 12:30:31,620 - WARNING - We are being rate limited. Retrying in 0.10 seconds. Handled under the bucket "697889935285289000:None:/channels/{channel_id}/messages/{message_id}/reactions/{emoji}/@me"
2021-01-03 12:30:33,787 - WARNING - We are being rate limited. Retrying in 0.09 seconds. Handled under the bucket "697889935285289000:None:/channels/{channel_id}/messages/{message_id}/reactions/{emoji}/@me"
2021-01-03 13:02:02,252 - WARNING - We are being rate limited. Retrying in 0.05 seconds. Handled under the bucket "697889935285289000:None:/channels/{channel_id}/messages/{message_id}/reactions/{emoji}/@me"
2021-01-03 13:02:11,187 - WARNING - We are being rate limited. Retrying in 0.10 seconds. Handled under the bucket "697889935285289000:None:/channels/{channel_id}/messages/{message_id}/reactions/{emoji}/@me"
2021-01-03 13:02:13,176 - WARNING - We are being rate limited. Retrying in 0.07 seconds. Handled under the bucket "697889935285289000:None:/channels/{channel_id}/messages/{message_id}/reactions/{emoji}/@me"
Ignoring exception in command None:
discord.ext.commands.errors.CommandNotFound: Command "&automod" is not found
Ignoring exception in command None:
discord.ext.commands.errors.CommandNotFound: Command "&automod" is not found
2021-01-03 14:01:31,089 - WARNING - We are being rate limited. Retrying in 0.10 seconds. Handled under the bucket "697889935285289000:None:/channels/{channel_id}/messages/{message_id}/reactions/{emoji}/@me"
Ignoring exception in command None:
discord.ext.commands.errors.CommandNotFound: Command "&automod" is not found
Ignoring exception in command None:
discord.ext.commands.errors.CommandNotFound: Command "&unmute" is not found
Ignoring exception in command None:
discord.ext.commands.errors.CommandNotFound: Command "&unmute" is not found
Ignoring exception in command None:
discord.ext.commands.errors.CommandNotFound: Command "&help" is not found
Ignoring exception in command None:
discord.ext.commands.errors.CommandNotFound: Command "&unmute" is not found
Ignoring exception in command None:
discord.ext.commands.errors.CommandNotFound: Command "&unmute" is not found
Ignoring exception in command None:
discord.ext.commands.errors.CommandNotFound: Command "&unmute" is not found
2021-01-04 14:08:29,030 - WARNING - We are being rate limited. Retrying in 0.10 seconds. Handled under the bucket "728968371458146374:None:/channels/{channel_id}/messages/{message_id}/reactions/{emoji}/@me"
2021-01-04 14:08:55,239 - WARNING - We are being rate limited. Retrying in 0.10 seconds. Handled under the bucket "729455686932627459:None:/channels/{channel_id}/messages/{message_id}/reactions/{emoji}/@me"
2021-01-04 14:09:31,548 - WARNING - We are being rate limited. Retrying in 0.07 seconds. Handled under the bucket "729455700186628116:None:/channels/{channel_id}/messages/{message_id}/reactions/{emoji}/@me"
Ignoring exception in command None:
discord.ext.commands.errors.CommandNotFound: Command "&log_channel" is not found
Ignoring exception in command None:
discord.ext.commands.errors.CommandNotFound: Command "&log_channel" is not found
Ignoring exception in command None:
discord.ext.commands.errors.CommandNotFound: Command "&help" is not found
Ignoring exception in command None:
discord.ext.commands.errors.CommandNotFound: Command "&help" is not found
Ignoring exception in command None:
discord.ext.commands.errors.CommandNotFound: Command "&help" is not found
Vérification de la base de donnée...

Suppression de la commande help...
Effectué!

Génération des modules logs...
logs/messageEdit.py
Lancement du module messageEdit
logs/voiceConnection.py
Lancement du module voiceConnection
logs/guildChannelCreate.py
Lancement du module guildChannelCreate
logs/guildMemberJoin.py
Lancement du module guildMemberJoin
logs/guildRoleDelete.py
Lancement du module guildRoleDelete
logs/guildChannelDelete.py
Lancement du module guildChannelDelete
logs/messageAddReaction.py
Lancement du module messageAddReaction
logs/guildUserUpdate.py
Lancement du module guildUserUpdate
logs/voiceUpdate.py
Lancement du module voiceUpdate
logs/voiceSelfUpdate.py
Lancement du module voiceSelfUpdate
logs/messageRemoveReaction.py
Lancement du module messageRemoveReaction
logs/messageCreate.py
Lancement du module messageCreate
logs/guildRoleCreate.py
Lancement du module guildRoleCreate
logs/guildMemberLeave.py
Lancement du module guildMemberLeave
logs/messageDelete.py
Lancement du module messageDelete
logs/voiceSwitch.py
Lancement du module voiceSwitch
logs/guildMemberUpdate.py
Lancement du module guildMemberUpdate

Génération des modules commandes...
Lancement du module help_command
Lancement du module administration
Lancement du module moderation

Lancement du bot...
UMMBOT est prêt!
Lien d'invitation: https://discord.com/oauth2/authorize?client_id=677213520529457152&scope=bot&permissions=8

Pour inviter UMMBot, veillez copier ce lien et mettre au bot la permission administrateur.
Une fois rejoint, veillez déplacer le rôle UMMBot tout en haut de la liste des rôles.
En cas de problème, veillez contacter Bretzel_#2246.
messageDelete.py -> Bot delete
messageDelete.py -> Bot delete
messageDelete.py -> Bot delete
messageDelete.py -> Bot delete
messageDelete.py -> Bot delete
messageDelete.py -> Bot delete
messageDelete.py -> Bot delete
messageDelete.py -> Bot delete
messageDelete.py -> Bot delete
messageDelete.py -> Bot delete
messageDelete.py -> Bot delete
messageDelete.py -> Bot delete
messageDelete.py -> Bot delete
New guild ! 728745118701584465
Guild (728745118701584465) db created
2021-01-04 16:31:54,099 - WARNING - We are being rate limited. Retrying in 0.09 seconds. Handled under the bucket "728968371458146374:None:/channels/{channel_id}/messages/{message_id}/reactions/{emoji}/@me"
2021-01-04 16:32:08,456 - WARNING - We are being rate limited. Retrying in 0.11 seconds. Handled under the bucket "729455710810931260:None:/channels/{channel_id}/messages/{message_id}/reactions/{emoji}/@me"
2021-01-04 16:32:15,502 - WARNING - We are being rate limited. Retrying in 0.07 seconds. Handled under the bucket "729455721414000711:None:/channels/{channel_id}/messages/{message_id}/reactions/{emoji}/@me"
2021-01-04 16:32:32,973 - WARNING - We are being rate limited. Retrying in 0.10 seconds. Handled under the bucket "728968371458146374:None:/channels/{channel_id}/messages/{message_id}/reactions/{emoji}/@me"
2021-01-04 16:32:41,097 - WARNING - We are being rate limited. Retrying in 3.44 seconds. Handled under the bucket "729455686932627459:None:/channels/{channel_id}/messages/{message_id}"
2021-01-04 16:32:46,332 - WARNING - We are being rate limited. Retrying in 3.52 seconds. Handled under the bucket "729455700186628116:None:/channels/{channel_id}/messages/{message_id}"
2021-01-04 16:32:47,485 - WARNING - We are being rate limited. Retrying in 2.21 seconds. Handled under the bucket "729455686932627459:None:/channels/{channel_id}/messages/{message_id}"
2021-01-04 16:32:51,457 - WARNING - We are being rate limited. Retrying in 3.38 seconds. Handled under the bucket "729455686932627459:None:/channels/{channel_id}/messages/{message_id}"
2021-01-04 16:32:51,566 - WARNING - We are being rate limited. Retrying in 3.44 seconds. Handled under the bucket "729455700186628116:None:/channels/{channel_id}/messages/{message_id}"
2021-01-04 16:32:56,492 - WARNING - We are being rate limited. Retrying in 3.48 seconds. Handled under the bucket "729455686932627459:None:/channels/{channel_id}/messages/{message_id}"
2021-01-04 16:32:56,642 - WARNING - We are being rate limited. Retrying in 3.49 seconds. Handled under the bucket "729455700186628116:None:/channels/{channel_id}/messages/{message_id}"
2021-01-04 16:32:57,879 - WARNING - We are being rate limited. Retrying in 3.53 seconds. Handled under the bucket "729455710810931260:None:/channels/{channel_id}/messages/{message_id}"
2021-01-04 16:33:01,714 - WARNING - We are being rate limited. Retrying in 3.42 seconds. Handled under the bucket "729455686932627459:None:/channels/{channel_id}/messages/{message_id}"
2021-01-04 16:33:02,239 - WARNING - We are being rate limited. Retrying in 3.06 seconds. Handled under the bucket "729455700186628116:None:/channels/{channel_id}/messages/{message_id}"
2021-01-04 16:33:03,220 - WARNING - We are being rate limited. Retrying in 3.35 seconds. Handled under the bucket "729455710810931260:None:/channels/{channel_id}/messages/{message_id}"
2021-01-04 16:33:05,723 - WARNING - We are being rate limited. Retrying in 3.54 seconds. Handled under the bucket "729455721414000711:None:/channels/{channel_id}/messages/{message_id}"
2021-01-04 16:33:06,762 - WARNING - We are being rate limited. Retrying in 3.52 seconds. Handled under the bucket "729455686932627459:None:/channels/{channel_id}/messages/{message_id}"
2021-01-04 16:33:07,074 - WARNING - We are being rate limited. Retrying in 3.39 seconds. Handled under the bucket "729455700186628116:None:/channels/{channel_id}/messages/{message_id}"
2021-01-04 16:33:08,254 - WARNING - We are being rate limited. Retrying in 3.47 seconds. Handled under the bucket "729455710810931260:None:/channels/{channel_id}/messages/{message_id}"
2021-01-04 16:33:10,987 - WARNING - We are being rate limited. Retrying in 3.42 seconds. Handled under the bucket "729455721414000711:None:/channels/{channel_id}/messages/{message_id}"
2021-01-04 16:33:12,419 - WARNING - We are being rate limited. Retrying in 3.17 seconds. Handled under the bucket "729455700186628116:None:/channels/{channel_id}/messages/{message_id}"
2021-01-04 16:33:13,370 - WARNING - We are being rate limited. Retrying in 2.05 seconds. Handled under the bucket "729455686932627459:None:/channels/{channel_id}/messages/{message_id}"
2021-01-04 16:33:13,382 - WARNING - We are being rate limited. Retrying in 3.52 seconds. Handled under the bucket "729455710810931260:None:/channels/{channel_id}/messages/{message_id}"
2021-01-04 16:33:17,086 - WARNING - We are being rate limited. Retrying in 3.52 seconds. Handled under the bucket "729455686932627459:None:/channels/{channel_id}/messages/{message_id}"
2021-01-04 16:33:17,206 - WARNING - We are being rate limited. Retrying in 3.52 seconds. Handled under the bucket "729455700186628116:None:/channels/{channel_id}/messages/{message_id}"
2021-01-04 16:33:18,609 - WARNING - We are being rate limited. Retrying in 3.44 seconds. Handled under the bucket "729455710810931260:None:/channels/{channel_id}/messages/{message_id}"
2021-01-04 16:33:21,190 - WARNING - We are being rate limited. Retrying in 3.53 seconds. Handled under the bucket "729455721414000711:None:/channels/{channel_id}/messages/{message_id}"
2021-01-04 16:33:22,310 - WARNING - We are being rate limited. Retrying in 3.44 seconds. Handled under the bucket "729455686932627459:None:/channels/{channel_id}/messages/{message_id}"
2021-01-04 16:33:22,402 - WARNING - We are being rate limited. Retrying in 3.47 seconds. Handled under the bucket "729455700186628116:None:/channels/{channel_id}/messages/{message_id}"
2021-01-04 16:33:26,387 - WARNING - We are being rate limited. Retrying in 3.48 seconds. Handled under the bucket "729455721414000711:None:/channels/{channel_id}/messages/{message_id}"
2021-01-04 16:33:26,817 - WARNING - We are being rate limited. Retrying in 0.36 seconds. Handled under the bucket "729455710810931260:None:/channels/{channel_id}/messages/{message_id}"
2021-01-04 16:33:27,378 - WARNING - We are being rate limited. Retrying in 3.53 seconds. Handled under the bucket "729455686932627459:None:/channels/{channel_id}/messages/{message_id}"
2021-01-04 16:33:27,513 - WARNING - We are being rate limited. Retrying in 3.51 seconds. Handled under the bucket "729455700186628116:None:/channels/{channel_id}/messages/{message_id}"
2021-01-04 16:33:32,634 - WARNING - We are being rate limited. Retrying in 3.51 seconds. Handled under the bucket "729455700186628116:None:/channels/{channel_id}/messages/{message_id}"
2021-01-04 16:33:37,765 - WARNING - We are being rate limited. Retrying in 3.52 seconds. Handled under the bucket "729455700186628116:None:/channels/{channel_id}/messages/{message_id}"
2021-01-04 16:33:42,959 - WARNING - We are being rate limited. Retrying in 3.48 seconds. Handled under the bucket "729455700186628116:None:/channels/{channel_id}/messages/{message_id}"
2021-01-04 16:33:48,070 - WARNING - We are being rate limited. Retrying in 3.51 seconds. Handled under the bucket "729455700186628116:None:/channels/{channel_id}/messages/{message_id}"
2021-01-04 16:34:49,402 - WARNING - We are being rate limited. Retrying in 0.04 seconds. Handled under the bucket "728968371458146374:None:/channels/{channel_id}/messages/{message_id}/reactions/{emoji}/@me"
2021-01-04 16:34:57,107 - WARNING - We are being rate limited. Retrying in 0.11 seconds. Handled under the bucket "728968371458146374:None:/channels/{channel_id}/messages/{message_id}/reactions/{emoji}/@me"
2021-01-04 16:35:05,887 - WARNING - We are being rate limited. Retrying in 0.10 seconds. Handled under the bucket "728968371458146374:None:/channels/{channel_id}/messages/{message_id}/reactions/{emoji}/@me"
2021-01-04 16:35:07,598 - WARNING - We are being rate limited. Retrying in 0.08 seconds. Handled under the bucket "728968371458146374:None:/channels/{channel_id}/messages/{message_id}/reactions/{emoji}/@me"
2021-01-04 16:35:22,278 - WARNING - We are being rate limited. Retrying in 0.09 seconds. Handled under the bucket "728968371458146374:None:/channels/{channel_id}/messages/{message_id}/reactions/{emoji}/@me"
2021-01-04 16:35:25,313 - WARNING - We are being rate limited. Retrying in 0.10 seconds. Handled under the bucket "728968371458146374:None:/channels/{channel_id}/messages/{message_id}/reactions/{emoji}/@me"
2021-01-04 16:35:33,316 - WARNING - We are being rate limited. Retrying in 0.09 seconds. Handled under the bucket "728968371458146374:None:/channels/{channel_id}/messages/{message_id}/reactions/{emoji}/@me"
2021-01-04 16:35:43,840 - WARNING - We are being rate limited. Retrying in 0.11 seconds. Handled under the bucket "728968371458146374:None:/channels/{channel_id}/messages/{message_id}/reactions/{emoji}/@me"
2021-01-04 16:35:55,967 - WARNING - We are being rate limited. Retrying in 0.09 seconds. Handled under the bucket "728968371458146374:None:/channels/{channel_id}/messages/{message_id}/reactions/{emoji}/@me"
2021-01-04 16:36:06,047 - WARNING - We are being rate limited. Retrying in 0.08 seconds. Handled under the bucket "728968371458146374:None:/channels/{channel_id}/messages/{message_id}/reactions/{emoji}/@me"
2021-01-04 16:36:12,410 - WARNING - We are being rate limited. Retrying in 0.05 seconds. Handled under the bucket "728968371458146374:None:/channels/{channel_id}/messages/{message_id}/reactions/{emoji}/@me"
2021-01-04 16:36:19,744 - WARNING - We are being rate limited. Retrying in 0.03 seconds. Handled under the bucket "728968371458146374:None:/channels/{channel_id}/messages/{message_id}/reactions/{emoji}/@me"
2021-01-04 16:37:12,873 - WARNING - We are being rate limited. Retrying in 0.03 seconds. Handled under the bucket "728968371458146374:None:/channels/{channel_id}/messages/{message_id}/reactions/{emoji}/@me"
2021-01-04 16:37:22,736 - WARNING - We are being rate limited. Retrying in 0.02 seconds. Handled under the bucket "728968371458146374:None:/channels/{channel_id}/messages/{message_id}/reactions/{emoji}/@me"
2021-01-04 16:37:24,650 - WARNING - We are being rate limited. Retrying in 0.10 seconds. Handled under the bucket "728968371458146374:None:/channels/{channel_id}/messages/{message_id}/reactions/{emoji}/@me"
2021-01-04 16:37:42,465 - WARNING - We are being rate limited. Retrying in 0.07 seconds. Handled under the bucket "728968371458146374:None:/channels/{channel_id}/messages/{message_id}/reactions/{emoji}/@me"
2021-01-04 16:37:46,875 - WARNING - We are being rate limited. Retrying in 0.11 seconds. Handled under the bucket "728968371458146374:None:/channels/{channel_id}/messages/{message_id}/reactions/{emoji}/@me"
2021-01-04 16:38:27,732 - WARNING - We are being rate limited. Retrying in 0.05 seconds. Handled under the bucket "728968371458146374:None:/channels/{channel_id}/messages/{message_id}/reactions/{emoji}/@me"
2021-01-04 16:39:19,360 - WARNING - We are being rate limited. Retrying in 0.10 seconds. Handled under the bucket "728968371458146374:None:/channels/{channel_id}/messages/{message_id}/reactions/{emoji}/@me"
2021-01-04 16:39:54,121 - WARNING - We are being rate limited. Retrying in 0.06 seconds. Handled under the bucket "728968371458146374:None:/channels/{channel_id}/messages/{message_id}/reactions/{emoji}/@me"
2021-01-04 16:43:43,808 - WARNING - We are being rate limited. Retrying in 0.10 seconds. Handled under the bucket "728968371458146374:None:/channels/{channel_id}/messages/{message_id}/reactions/{emoji}/@me"
2021-01-04 16:43:48,337 - WARNING - We are being rate limited. Retrying in 0.09 seconds. Handled under the bucket "728968371458146374:None:/channels/{channel_id}/messages/{message_id}/reactions/{emoji}/@me"
2021-01-04 16:43:52,731 - WARNING - We are being rate limited. Retrying in 0.04 seconds. Handled under the bucket "728968371458146374:None:/channels/{channel_id}/messages/{message_id}/reactions/{emoji}/@me"
2021-01-04 16:43:57,136 - WARNING - We are being rate limited. Retrying in 0.09 seconds. Handled under the bucket "728968371458146374:None:/channels/{channel_id}/messages/{message_id}/reactions/{emoji}/@me"
2021-01-04 16:53:58,797 - WARNING - We are being rate limited. Retrying in 0.10 seconds. Handled under the bucket "729455686932627459:None:/channels/{channel_id}/messages/{message_id}/reactions/{emoji}/@me"
2021-01-04 16:54:15,739 - WARNING - We are being rate limited. Retrying in 0.07 seconds. Handled under the bucket "729455686932627459:None:/channels/{channel_id}/messages/{message_id}/reactions/{emoji}/@me"
2021-01-04 17:07:45,737 - WARNING - We are being rate limited. Retrying in 0.10 seconds. Handled under the bucket "729455686932627459:None:/channels/{channel_id}/messages/{message_id}/reactions/{emoji}/@me"
Vérification de la base de donnée...

Suppression de la commande help...
Effectué!

Génération des modules logs...
logs/messageEdit.py
Lancement du module messageEdit
logs/voiceConnection.py
Lancement du module voiceConnection
logs/guildChannelCreate.py
Lancement du module guildChannelCreate
logs/guildMemberJoin.py
Lancement du module guildMemberJoin
logs/guildRoleDelete.py
Lancement du module guildRoleDelete
logs/guildChannelDelete.py
Lancement du module guildChannelDelete
logs/messageAddReaction.py
Lancement du module messageAddReaction
logs/guildUserUpdate.py
Lancement du module guildUserUpdate
logs/voiceUpdate.py
Lancement du module voiceUpdate
logs/voiceSelfUpdate.py
Lancement du module voiceSelfUpdate
logs/messageRemoveReaction.py
Lancement du module messageRemoveReaction
logs/messageCreate.py
Lancement du module messageCreate
logs/guildRoleCreate.py
Lancement du module guildRoleCreate
logs/guildMemberLeave.py
Lancement du module guildMemberLeave
logs/messageDelete.py
Lancement du module messageDelete
logs/voiceSwitch.py
Lancement du module voiceSwitch
logs/guildMemberUpdate.py
Lancement du module guildMemberUpdate

Génération des modules commandes...
Lancement du module help_command
Lancement du module administration
Lancement du module moderation

Lancement du bot...
UMMBOT est prêt!
Lien d'invitation: https://discord.com/oauth2/authorize?client_id=677213520529457152&scope=bot&permissions=8

Pour inviter UMMBot, veillez copier ce lien et mettre au bot la permission administrateur.
Une fois rejoint, veillez déplacer le rôle UMMBot tout en haut de la liste des rôles.
En cas de problème, veillez contacter Bretzel_#2246.
2021-01-04 17:21:32,005 - WARNING - We are being rate limited. Retrying in 0.09 seconds. Handled under the bucket "729455686932627459:None:/channels/{channel_id}/messages/{message_id}/reactions/{emoji}/@me"
2021-01-04 17:21:39,055 - WARNING - We are being rate limited. Retrying in 0.10 seconds. Handled under the bucket "729455700186628116:None:/channels/{channel_id}/messages/{message_id}/reactions/{emoji}/@me"
2021-01-04 17:22:20,668 - WARNING - We are being rate limited. Retrying in 0.09 seconds. Handled under the bucket "728968371458146374:None:/channels/{channel_id}/messages/{message_id}/reactions/{emoji}/@me"
Ignoring exception in command None:
discord.ext.commands.errors.CommandNotFound: Command "&sanctions" is not found
2021-01-12 02:22:17,878 - ERROR - Attempting a reconnect in 0.68s
Traceback (most recent call last):
  File "/usr/local/lib/python3.8/dist-packages/discord/client.py", line 548, in connect
    self.ws = await asyncio.wait_for(coro, timeout=60.0)
  File "/usr/lib/python3.8/asyncio/tasks.py", line 494, in wait_for
    return fut.result()
  File "/usr/local/lib/python3.8/dist-packages/discord/gateway.py", line 306, in from_client
    socket = await client.http.ws_connect(gateway)
  File "/usr/local/lib/python3.8/dist-packages/discord/http.py", line 132, in ws_connect
    return await self.__session.ws_connect(url, **kwargs)
  File "/usr/local/lib/python3.8/dist-packages/aiohttp/client.py", line 733, in _ws_connect
    raise WSServerHandshakeError(
aiohttp.client_exceptions.WSServerHandshakeError: 502, message='Invalid response status', url=URL('wss://gateway.discord.gg/?encoding=json&v=6&compress=zlib-stream')
2021-01-12 02:22:20,156 - ERROR - Attempting a reconnect in 3.43s
Traceback (most recent call last):
  File "/usr/local/lib/python3.8/dist-packages/discord/client.py", line 548, in connect
    self.ws = await asyncio.wait_for(coro, timeout=60.0)
  File "/usr/lib/python3.8/asyncio/tasks.py", line 494, in wait_for
    return fut.result()
  File "/usr/local/lib/python3.8/dist-packages/discord/gateway.py", line 306, in from_client
    socket = await client.http.ws_connect(gateway)
  File "/usr/local/lib/python3.8/dist-packages/discord/http.py", line 132, in ws_connect
    return await self.__session.ws_connect(url, **kwargs)
  File "/usr/local/lib/python3.8/dist-packages/aiohttp/client.py", line 733, in _ws_connect
    raise WSServerHandshakeError(
aiohttp.client_exceptions.WSServerHandshakeError: 502, message='Invalid response status', url=URL('wss://gateway.discord.gg/?encoding=json&v=6&compress=zlib-stream')
2021-01-12 02:22:55,670 - ERROR - Attempting a reconnect in 4.90s
Traceback (most recent call last):
  File "/usr/local/lib/python3.8/dist-packages/discord/http.py", line 910, in get_gateway
    data = await self.request(Route('GET', '/gateway'))
  File "/usr/local/lib/python3.8/dist-packages/discord/http.py", line 256, in request
    raise DiscordServerError(r, data)
discord.errors.DiscordServerError: 502 Bad Gateway (error code: 0): <html>
<head><title>502 Bad Gateway</title></head>
<body>
<center><h1>502 Bad Gateway</h1></center>
<hr><center>cloudflare</center>
</body>
</html>


The above exception was the direct cause of the following exception:

Traceback (most recent call last):
  File "/usr/local/lib/python3.8/dist-packages/discord/client.py", line 548, in connect
    self.ws = await asyncio.wait_for(coro, timeout=60.0)
  File "/usr/lib/python3.8/asyncio/tasks.py", line 494, in wait_for
    return fut.result()
  File "/usr/local/lib/python3.8/dist-packages/discord/gateway.py", line 305, in from_client
    gateway = gateway or await client.http.get_gateway()
  File "/usr/local/lib/python3.8/dist-packages/discord/http.py", line 912, in get_gateway
    raise GatewayNotFound() from exc
discord.errors.GatewayNotFound: The gateway to connect to discord was not found.
Ignoring exception in command None:
discord.ext.commands.errors.CommandNotFound: Command "ping" is not found
Ignoring exception in on_message_edit
Traceback (most recent call last):
  File "/usr/local/lib/python3.8/dist-packages/discord/client.py", line 333, in _run_event
    await coro(*args, **kwargs)
  File "/root/bot/UMMBOT/logs/messageEdit.py", line 90, in on_message_edit
    logs_channels = cursor.fetchall()[0]
IndexError: list index out of range
Ignoring exception in command None:
discord.ext.commands.errors.CommandNotFound: Command "&help" is not found
Ignoring exception in command None:
discord.ext.commands.errors.CommandNotFound: Command "&help" is not found
Ignoring exception in command None:
discord.ext.commands.errors.CommandNotFound: Command "&case" is not found
Ignoring exception in command None:
discord.ext.commands.errors.CommandNotFound: Command "&help" is not found
Ignoring exception in command None:
discord.ext.commands.errors.CommandNotFound: Command "&asciify" is not found
Vérification de la base de donnée...

Suppression de la commande help...
Effectué!

Génération des modules logs...
logs/messageEdit.py
Lancement du module messageEdit
logs/voiceConnection.py
Lancement du module voiceConnection
logs/guildChannelCreate.py
Lancement du module guildChannelCreate
logs/guildMemberJoin.py
Lancement du module guildMemberJoin
logs/guildRoleDelete.py
Lancement du module guildRoleDelete
logs/guildChannelDelete.py
Lancement du module guildChannelDelete
logs/messageAddReaction.py
Lancement du module messageAddReaction
logs/guildUserUpdate.py
Lancement du module guildUserUpdate
logs/voiceUpdate.py
Lancement du module voiceUpdate
logs/voiceSelfUpdate.py
Lancement du module voiceSelfUpdate
logs/messageRemoveReaction.py
Lancement du module messageRemoveReaction
logs/messageCreate.py
Lancement du module messageCreate
logs/guildRoleCreate.py
Lancement du module guildRoleCreate
logs/guildMemberLeave.py
Lancement du module guildMemberLeave
logs/messageDelete.py
Lancement du module messageDelete
logs/voiceSwitch.py
Lancement du module voiceSwitch
logs/guildMemberUpdate.py
Lancement du module guildMemberUpdate

Génération des modules commandes...
Lancement du module help_command
Lancement du module administration
Lancement du module moderation

Lancement du bot...
UMMBOT est prêt!
Lien d'invitation: https://discord.com/oauth2/authorize?client_id=677213520529457152&scope=bot&permissions=8

Pour inviter UMMBot, veillez copier ce lien et mettre au bot la permission administrateur.
Une fois rejoint, veillez déplacer le rôle UMMBot tout en haut de la liste des rôles.
En cas de problème, veillez contacter Bretzel_#2246.
messageDelete.py -> Bot delete
['MUTE', 'test', 232920242110726144, 479920534931636225, '2021-01-04 17:22:30', 1, 17, 728745118701584465]
New guild ! 672867622731251739
Guild (672867622731251739) db created
New guild ! 805060685641678909
Guild (805060685641678909) db created
Vérification de la base de donnée...

Suppression de la commande help...
Effectué!

Génération des modules logs...
logs/messageEdit.py
Lancement du module messageEdit
logs/voiceConnection.py
Lancement du module voiceConnection
logs/guildChannelCreate.py
Lancement du module guildChannelCreate
logs/guildMemberJoin.py
Lancement du module guildMemberJoin
logs/guildRoleDelete.py
Lancement du module guildRoleDelete
logs/guildChannelDelete.py
Lancement du module guildChannelDelete
logs/messageAddReaction.py
Lancement du module messageAddReaction
logs/guildUserUpdate.py
Lancement du module guildUserUpdate
logs/voiceUpdate.py
Lancement du module voiceUpdate
logs/voiceSelfUpdate.py
Lancement du module voiceSelfUpdate
logs/messageRemoveReaction.py
Lancement du module messageRemoveReaction
logs/messageCreate.py
Lancement du module messageCreate
logs/guildRoleCreate.py
Lancement du module guildRoleCreate
logs/guildMemberLeave.py
Lancement du module guildMemberLeave
logs/messageDelete.py
Lancement du module messageDelete
logs/voiceSwitch.py
Lancement du module voiceSwitch
logs/guildMemberUpdate.py
Lancement du module guildMemberUpdate

Génération des modules commandes...
Lancement du module help_command
Lancement du module utility
Traceback (most recent call last):
  File "/usr/local/lib/python3.8/dist-packages/discord/ext/commands/bot.py", line 607, in _load_from_module_spec
    spec.loader.exec_module(lib)
  File "<frozen importlib._bootstrap_external>", line 783, in exec_module
  File "<frozen importlib._bootstrap>", line 219, in _call_with_frames_removed
  File "/root/bot/UMMBOT/cogs/utility.py", line 1, in <module>
    from PIL import Image
ModuleNotFoundError: No module named 'PIL'

The above exception was the direct cause of the following exception:

Traceback (most recent call last):
  File "UMM.py", line 79, in <module>
    bot.start_bot(TOKEN)
  File "UMM.py", line 57, in start_bot
    self.load_commands()
  File "UMM.py", line 46, in load_commands
    self.load_extension(f'cogs.{files}')
  File "/usr/local/lib/python3.8/dist-packages/discord/ext/commands/bot.py", line 664, in load_extension
    self._load_from_module_spec(spec, name)
  File "/usr/local/lib/python3.8/dist-packages/discord/ext/commands/bot.py", line 610, in _load_from_module_spec
    raise errors.ExtensionFailed(key, e) from e
discord.ext.commands.errors.ExtensionFailed: Extension 'cogs.utility' raised an error: ModuleNotFoundError: No module named 'PIL'
Vérification de la base de donnée...

Suppression de la commande help...
Effectué!

Génération des modules logs...
logs/messageEdit.py
Lancement du module messageEdit
logs/voiceConnection.py
Lancement du module voiceConnection
logs/guildChannelCreate.py
Lancement du module guildChannelCreate
logs/guildMemberJoin.py
Lancement du module guildMemberJoin
logs/guildRoleDelete.py
Lancement du module guildRoleDelete
logs/guildChannelDelete.py
Lancement du module guildChannelDelete
logs/messageAddReaction.py
Lancement du module messageAddReaction
logs/guildUserUpdate.py
Lancement du module guildUserUpdate
logs/voiceUpdate.py
Lancement du module voiceUpdate
logs/voiceSelfUpdate.py
Lancement du module voiceSelfUpdate
logs/messageRemoveReaction.py
Lancement du module messageRemoveReaction
logs/messageCreate.py
Lancement du module messageCreate
logs/guildRoleCreate.py
Lancement du module guildRoleCreate
logs/guildMemberLeave.py
Lancement du module guildMemberLeave
logs/messageDelete.py
Lancement du module messageDelete
logs/voiceSwitch.py
Lancement du module voiceSwitch
logs/guildMemberUpdate.py
Lancement du module guildMemberUpdate

Génération des modules commandes...
Lancement du module help_command
Lancement du module utility
Traceback (most recent call last):
  File "/usr/local/lib/python3.8/dist-packages/discord/ext/commands/bot.py", line 607, in _load_from_module_spec
    spec.loader.exec_module(lib)
  File "<frozen importlib._bootstrap_external>", line 783, in exec_module
  File "<frozen importlib._bootstrap>", line 219, in _call_with_frames_removed
  File "/root/bot/UMMBOT/cogs/utility.py", line 1, in <module>
    from PIL import Image
ModuleNotFoundError: No module named 'PIL'

The above exception was the direct cause of the following exception:

Traceback (most recent call last):
  File "UMM.py", line 79, in <module>
    bot.start_bot(TOKEN)
  File "UMM.py", line 57, in start_bot
    self.load_commands()
  File "UMM.py", line 46, in load_commands
    self.load_extension(f'cogs.{files}')
  File "/usr/local/lib/python3.8/dist-packages/discord/ext/commands/bot.py", line 664, in load_extension
    self._load_from_module_spec(spec, name)
  File "/usr/local/lib/python3.8/dist-packages/discord/ext/commands/bot.py", line 610, in _load_from_module_spec
    raise errors.ExtensionFailed(key, e) from e
discord.ext.commands.errors.ExtensionFailed: Extension 'cogs.utility' raised an error: ModuleNotFoundError: No module named 'PIL'
Vérification de la base de donnée...

Suppression de la commande help...
Effectué!

Génération des modules logs...
logs/messageEdit.py
Lancement du module messageEdit
logs/voiceConnection.py
Lancement du module voiceConnection
logs/guildChannelCreate.py
Lancement du module guildChannelCreate
logs/guildMemberJoin.py
Lancement du module guildMemberJoin
logs/guildRoleDelete.py
Lancement du module guildRoleDelete
logs/guildChannelDelete.py
Lancement du module guildChannelDelete
logs/messageAddReaction.py
Lancement du module messageAddReaction
logs/guildUserUpdate.py
Lancement du module guildUserUpdate
logs/voiceUpdate.py
Lancement du module voiceUpdate
logs/voiceSelfUpdate.py
Lancement du module voiceSelfUpdate
logs/messageRemoveReaction.py
Lancement du module messageRemoveReaction
logs/messageCreate.py
Lancement du module messageCreate
logs/guildRoleCreate.py
Lancement du module guildRoleCreate
logs/guildMemberLeave.py
Lancement du module guildMemberLeave
logs/messageDelete.py
Lancement du module messageDelete
logs/voiceSwitch.py
Lancement du module voiceSwitch
logs/guildMemberUpdate.py
Lancement du module guildMemberUpdate

Génération des modules commandes...
Lancement du module help_command
Lancement du module utility
Traceback (most recent call last):
  File "/usr/local/lib/python3.8/dist-packages/discord/ext/commands/bot.py", line 607, in _load_from_module_spec
    spec.loader.exec_module(lib)
  File "<frozen importlib._bootstrap_external>", line 783, in exec_module
  File "<frozen importlib._bootstrap>", line 219, in _call_with_frames_removed
  File "/root/bot/UMMBOT/cogs/utility.py", line 15, in <module>
    font = ImageFont.truetype("cour.ttf", FONT_SIZE)
  File "/usr/local/lib/python3.8/dist-packages/PIL/ImageFont.py", line 852, in truetype
    return freetype(font)
  File "/usr/local/lib/python3.8/dist-packages/PIL/ImageFont.py", line 849, in freetype
    return FreeTypeFont(font, size, index, encoding, layout_engine)
  File "/usr/local/lib/python3.8/dist-packages/PIL/ImageFont.py", line 209, in __init__
    self.font = core.getfont(
OSError: cannot open resource

The above exception was the direct cause of the following exception:

Traceback (most recent call last):
  File "UMM.py", line 79, in <module>
    bot.start_bot(TOKEN)
  File "UMM.py", line 57, in start_bot
    self.load_commands()
  File "UMM.py", line 46, in load_commands
    self.load_extension(f'cogs.{files}')
  File "/usr/local/lib/python3.8/dist-packages/discord/ext/commands/bot.py", line 664, in load_extension
    self._load_from_module_spec(spec, name)
  File "/usr/local/lib/python3.8/dist-packages/discord/ext/commands/bot.py", line 610, in _load_from_module_spec
    raise errors.ExtensionFailed(key, e) from e
discord.ext.commands.errors.ExtensionFailed: Extension 'cogs.utility' raised an error: OSError: cannot open resource
Ignoring exception in command None:
discord.ext.commands.errors.CommandNotFound: Command "&help" is not found
Vérification de la base de donnée...

Suppression de la commande help...
Effectué!

Génération des modules logs...
logs/messageEdit.py
Lancement du module messageEdit
logs/voiceConnection.py
Lancement du module voiceConnection
logs/guildChannelCreate.py
Lancement du module guildChannelCreate
logs/guildMemberJoin.py
Lancement du module guildMemberJoin
logs/guildRoleDelete.py
Lancement du module guildRoleDelete
logs/guildChannelDelete.py
Lancement du module guildChannelDelete
logs/messageAddReaction.py
Lancement du module messageAddReaction
logs/guildUserUpdate.py
Lancement du module guildUserUpdate
logs/voiceUpdate.py
Lancement du module voiceUpdate
logs/voiceSelfUpdate.py
Lancement du module voiceSelfUpdate
logs/messageRemoveReaction.py
Lancement du module messageRemoveReaction
logs/messageCreate.py
Lancement du module messageCreate
logs/guildRoleCreate.py
Lancement du module guildRoleCreate
logs/guildMemberLeave.py
Lancement du module guildMemberLeave
logs/messageDelete.py
Lancement du module messageDelete
logs/voiceSwitch.py
Lancement du module voiceSwitch
logs/guildMemberUpdate.py
Lancement du module guildMemberUpdate

Génération des modules commandes...
Lancement du module help_command
Lancement du module utility
Lancement du module administration
Lancement du module moderation

Lancement du bot...
UMMBOT est prêt!
Lien d'invitation: https://discord.com/oauth2/authorize?client_id=677213520529457152&scope=bot&permissions=8

Pour inviter UMMBot, veillez copier ce lien et mettre au bot la permission administrateur.
Une fois rejoint, veillez déplacer le rôle UMMBot tout en haut de la liste des rôles.
En cas de problème, veillez contacter Bretzel_#2246.
Ignoring exception in command None:
discord.ext.commands.errors.CommandNotFound: Command "&help" is not found
2021-01-31 00:20:13,528 - WARNING - We are being rate limited. Retrying in 0.11 seconds. Handled under the bucket "805060685641678912:None:/channels/{channel_id}/messages/{message_id}/reactions/{emoji}/@me"
2021-01-31 00:20:15,110 - WARNING - We are being rate limited. Retrying in 0.07 seconds. Handled under the bucket "805060685641678912:None:/channels/{channel_id}/messages/{message_id}/reactions/{emoji}/@me"
Vérification de la base de donnée...

Suppression de la commande help...
Effectué!

Génération des modules logs...
logs/messageEdit.py
Lancement du module messageEdit
logs/voiceConnection.py
Lancement du module voiceConnection
logs/guildChannelCreate.py
Lancement du module guildChannelCreate
logs/guildMemberJoin.py
Lancement du module guildMemberJoin
logs/guildRoleDelete.py
Lancement du module guildRoleDelete
logs/guildChannelDelete.py
Lancement du module guildChannelDelete
logs/messageAddReaction.py
Lancement du module messageAddReaction
logs/guildUserUpdate.py
Lancement du module guildUserUpdate
logs/voiceUpdate.py
Lancement du module voiceUpdate
logs/voiceSelfUpdate.py
Lancement du module voiceSelfUpdate
logs/messageRemoveReaction.py
Lancement du module messageRemoveReaction
logs/messageCreate.py
Lancement du module messageCreate
logs/guildRoleCreate.py
Lancement du module guildRoleCreate
logs/guildMemberLeave.py
Lancement du module guildMemberLeave
logs/messageDelete.py
Lancement du module messageDelete
logs/voiceSwitch.py
Lancement du module voiceSwitch
logs/guildMemberUpdate.py
Lancement du module guildMemberUpdate

Génération des modules commandes...
Lancement du module help_command
Lancement du module utility
Lancement du module administration
Lancement du module moderation

Lancement du bot...
UMMBOT est prêt!
Lien d'invitation: https://discord.com/oauth2/authorize?client_id=677213520529457152&scope=bot&permissions=8

Pour inviter UMMBot, veillez copier ce lien et mettre au bot la permission administrateur.
Une fois rejoint, veillez déplacer le rôle UMMBot tout en haut de la liste des rôles.
En cas de problème, veillez contacter Bretzel_#2246.
2021-01-31 00:27:05,580 - WARNING - We are being rate limited. Retrying in 0.11 seconds. Handled under the bucket "805060685641678912:None:/channels/{channel_id}/messages/{message_id}/reactions/{emoji}/@me"
2021-01-31 00:27:08,853 - WARNING - We are being rate limited. Retrying in 0.09 seconds. Handled under the bucket "805060685641678912:None:/channels/{channel_id}/messages/{message_id}/reactions/{emoji}/@me"
Ignoring exception in command None:
discord.ext.commands.errors.CommandNotFound: Command "&help" is not found
Ignoring exception in command None:
discord.ext.commands.errors.CommandNotFound: Command "&help" is not found
Ignoring exception in command None:
discord.ext.commands.errors.CommandNotFound: Command "&help" is not found
Vérification de la base de donnée...

Suppression de la commande help...
Effectué!

Génération des modules logs...
logs/messageEdit.py
Lancement du module messageEdit
logs/voiceConnection.py
Lancement du module voiceConnection
logs/guildChannelCreate.py
Lancement du module guildChannelCreate
logs/guildMemberJoin.py
Lancement du module guildMemberJoin
logs/guildRoleDelete.py
Lancement du module guildRoleDelete
logs/guildChannelDelete.py
Lancement du module guildChannelDelete
logs/messageAddReaction.py
Lancement du module messageAddReaction
logs/guildUserUpdate.py
Lancement du module guildUserUpdate
logs/voiceUpdate.py
Lancement du module voiceUpdate
logs/voiceSelfUpdate.py
Lancement du module voiceSelfUpdate
logs/messageRemoveReaction.py
Lancement du module messageRemoveReaction
logs/messageCreate.py
Lancement du module messageCreate
logs/guildRoleCreate.py
Lancement du module guildRoleCreate
logs/guildMemberLeave.py
Lancement du module guildMemberLeave
logs/messageDelete.py
Lancement du module messageDelete
logs/voiceSwitch.py
Lancement du module voiceSwitch
logs/guildMemberUpdate.py
Lancement du module guildMemberUpdate

Génération des modules commandes...
Lancement du module help_command
Lancement du module administration
Lancement du module moderation
Lancement du module utils

Lancement du bot...
UMMBOT est prêt!
Lien d'invitation: https://discord.com/oauth2/authorize?client_id=677213520529457152&scope=bot&permissions=8

Pour inviter UMMBot, veillez copier ce lien et mettre au bot la permission administrateur.
Une fois rejoint, veillez déplacer le rôle UMMBot tout en haut de la liste des rôles.
En cas de problème, veillez contacter Bretzel_#2246.
2021-01-31 00:45:01,487 - WARNING - We are being rate limited. Retrying in 0.09 seconds. Handled under the bucket "805060685641678912:None:/channels/{channel_id}/messages/{message_id}/reactions/{emoji}/@me"
Ignoring exception in command None:
discord.ext.commands.errors.CommandNotFound: Command "&help" is not found
Ignoring exception in command None:
discord.ext.commands.errors.CommandNotFound: Command "&help" is not found
Ignoring exception in command None:
discord.ext.commands.errors.CommandNotFound: Command "&help" is not found
Vérification de la base de donnée...

Suppression de la commande help...
Effectué!

Génération des modules logs...
logs/messageEdit.py
Lancement du module messageEdit
logs/voiceConnection.py
Lancement du module voiceConnection
logs/guildChannelCreate.py
Lancement du module guildChannelCreate
logs/guildMemberJoin.py
Lancement du module guildMemberJoin
logs/guildRoleDelete.py
Lancement du module guildRoleDelete
logs/guildChannelDelete.py
Lancement du module guildChannelDelete
logs/messageAddReaction.py
Lancement du module messageAddReaction
logs/guildUserUpdate.py
Lancement du module guildUserUpdate
logs/voiceUpdate.py
Lancement du module voiceUpdate
logs/voiceSelfUpdate.py
Lancement du module voiceSelfUpdate
logs/messageRemoveReaction.py
Lancement du module messageRemoveReaction
logs/messageCreate.py
Lancement du module messageCreate
logs/guildRoleCreate.py
Lancement du module guildRoleCreate
logs/guildMemberLeave.py
Lancement du module guildMemberLeave
logs/messageDelete.py
Lancement du module messageDelete
logs/voiceSwitch.py
Lancement du module voiceSwitch
logs/guildMemberUpdate.py
Lancement du module guildMemberUpdate

Génération des modules commandes...
Lancement du module help_command
Lancement du module administration
Lancement du module utilitaire
Lancement du module moderation

Lancement du bot...
UMMBOT est prêt!
Lien d'invitation: https://discord.com/oauth2/authorize?client_id=677213520529457152&scope=bot&permissions=8

Pour inviter UMMBot, veillez copier ce lien et mettre au bot la permission administrateur.
Une fois rejoint, veillez déplacer le rôle UMMBot tout en haut de la liste des rôles.
En cas de problème, veillez contacter Bretzel_#2246.
2021-01-31 00:53:48,588 - WARNING - We are being rate limited. Retrying in 0.11 seconds. Handled under the bucket "805060685641678912:None:/channels/{channel_id}/messages/{message_id}/reactions/{emoji}/@me"
Ignoring exception in command asciify:
Traceback (most recent call last):
  File "/usr/local/lib/python3.8/dist-packages/discord/ext/commands/core.py", line 85, in wrapped
    ret = await coro(*args, **kwargs)
  File "/root/bot/UMMBOT/cogs/utilitaire.py", line 130, in asciify
    hexcode = check_hexcolor(hexcode)
  File "/root/bot/UMMBOT/cogs/utilitaire.py", line 93, in check_hexcolor
    return [convert_hex_rgb(hexcode[0]), convert_hex_rgb(hexcode[1])]
IndexError: tuple index out of range

The above exception was the direct cause of the following exception:

Traceback (most recent call last):
  File "/usr/local/lib/python3.8/dist-packages/discord/ext/commands/bot.py", line 903, in invoke
    await ctx.command.invoke(ctx)
  File "/usr/local/lib/python3.8/dist-packages/discord/ext/commands/core.py", line 859, in invoke
    await injected(*ctx.args, **ctx.kwargs)
  File "/usr/local/lib/python3.8/dist-packages/discord/ext/commands/core.py", line 94, in wrapped
    raise CommandInvokeError(exc) from exc
discord.ext.commands.errors.CommandInvokeError: Command raised an exception: IndexError: tuple index out of range
Ignoring exception in command asciify:
Traceback (most recent call last):
  File "/usr/local/lib/python3.8/dist-packages/discord/ext/commands/core.py", line 85, in wrapped
    ret = await coro(*args, **kwargs)
  File "/root/bot/UMMBOT/cogs/utilitaire.py", line 130, in asciify
    hexcode = check_hexcolor(hexcode)
  File "/root/bot/UMMBOT/cogs/utilitaire.py", line 93, in check_hexcolor
    return [convert_hex_rgb(hexcode[0]), convert_hex_rgb(hexcode[1])]
IndexError: tuple index out of range

The above exception was the direct cause of the following exception:

Traceback (most recent call last):
  File "/usr/local/lib/python3.8/dist-packages/discord/ext/commands/bot.py", line 903, in invoke
    await ctx.command.invoke(ctx)
  File "/usr/local/lib/python3.8/dist-packages/discord/ext/commands/core.py", line 859, in invoke
    await injected(*ctx.args, **ctx.kwargs)
  File "/usr/local/lib/python3.8/dist-packages/discord/ext/commands/core.py", line 94, in wrapped
    raise CommandInvokeError(exc) from exc
discord.ext.commands.errors.CommandInvokeError: Command raised an exception: IndexError: tuple index out of range
Ignoring exception in command asciify:
Traceback (most recent call last):
  File "/usr/local/lib/python3.8/dist-packages/discord/ext/commands/core.py", line 85, in wrapped
    ret = await coro(*args, **kwargs)
  File "/root/bot/UMMBOT/cogs/utilitaire.py", line 130, in asciify
    hexcode = check_hexcolor(hexcode)
  File "/root/bot/UMMBOT/cogs/utilitaire.py", line 93, in check_hexcolor
    return [convert_hex_rgb(hexcode[0]), convert_hex_rgb(hexcode[1])]
  File "/root/bot/UMMBOT/cogs/utilitaire.py", line 62, in convert_hex_rgb
    return ImageColor.getrgb(hexcode)
  File "/usr/local/lib/python3.8/dist-packages/PIL/ImageColor.py", line 116, in getrgb
    raise ValueError(f"unknown color specifier: {repr(color)}")
ValueError: unknown color specifier: 'dark'

The above exception was the direct cause of the following exception:

Traceback (most recent call last):
  File "/usr/local/lib/python3.8/dist-packages/discord/ext/commands/bot.py", line 903, in invoke
    await ctx.command.invoke(ctx)
  File "/usr/local/lib/python3.8/dist-packages/discord/ext/commands/core.py", line 859, in invoke
    await injected(*ctx.args, **ctx.kwargs)
  File "/usr/local/lib/python3.8/dist-packages/discord/ext/commands/core.py", line 94, in wrapped
    raise CommandInvokeError(exc) from exc
discord.ext.commands.errors.CommandInvokeError: Command raised an exception: ValueError: unknown color specifier: 'dark'
2021-02-02 10:58:53,719 - ERROR - Attempting a reconnect in 0.71s
Traceback (most recent call last):
  File "/usr/local/lib/python3.8/dist-packages/discord/client.py", line 548, in connect
    self.ws = await asyncio.wait_for(coro, timeout=60.0)
  File "/usr/lib/python3.8/asyncio/tasks.py", line 501, in wait_for
    raise exceptions.TimeoutError()
asyncio.exceptions.TimeoutError
2021-02-02 11:45:15,980 - WARNING - We are being rate limited. Retrying in 0.10 seconds. Handled under the bucket "805060685641678912:None:/channels/{channel_id}/messages/{message_id}/reactions/{emoji}/@me"
Ignoring exception in command None:
discord.ext.commands.errors.CommandNotFound: Command "aciify" is not found
2021-02-02 11:49:07,037 - WARNING - We are being rate limited. Retrying in 0.11 seconds. Handled under the bucket "805060685641678912:None:/channels/{channel_id}/messages/{message_id}/reactions/{emoji}/@me"
2021-02-02 11:49:11,676 - WARNING - We are being rate limited. Retrying in 0.11 seconds. Handled under the bucket "805060685641678912:None:/channels/{channel_id}/messages/{message_id}/reactions/{emoji}/@me"
2021-02-02 11:49:33,244 - WARNING - We are being rate limited. Retrying in 0.10 seconds. Handled under the bucket "805060685641678912:None:/channels/{channel_id}/messages/{message_id}/reactions/{emoji}/@me"
2021-02-02 11:49:37,829 - WARNING - We are being rate limited. Retrying in 0.09 seconds. Handled under the bucket "805060685641678912:None:/channels/{channel_id}/messages/{message_id}/reactions/{emoji}/@me"
2021-02-02 11:49:48,666 - WARNING - We are being rate limited. Retrying in 0.09 seconds. Handled under the bucket "805060685641678912:None:/channels/{channel_id}/messages/{message_id}/reactions/{emoji}/@me"
2021-02-02 11:49:52,366 - WARNING - We are being rate limited. Retrying in 0.08 seconds. Handled under the bucket "805060685641678912:None:/channels/{channel_id}/messages/{message_id}/reactions/{emoji}/@me"
2021-02-02 11:49:57,237 - WARNING - We are being rate limited. Retrying in 0.09 seconds. Handled under the bucket "805060685641678912:None:/channels/{channel_id}/messages/{message_id}/reactions/{emoji}/@me"
Ignoring exception in command None:
discord.ext.commands.errors.CommandNotFound: Command "asciffy" is not found
Ignoring exception in command None:
discord.ext.commands.errors.CommandNotFound: Command "&help" is not found
Ignoring exception in command None:
discord.ext.commands.errors.CommandNotFound: Command "&help" is not found
Ignoring exception in command None:
discord.ext.commands.errors.CommandNotFound: Command "&help" is not found
Ignoring exception in command None:
discord.ext.commands.errors.CommandNotFound: Command "&asciify" is not found
Ignoring exception in command None:
discord.ext.commands.errors.CommandNotFound: Command "&asciify" is not found
Ignoring exception in command None:
discord.ext.commands.errors.CommandNotFound: Command "&asciify" is not found
Ignoring exception in command None:
discord.ext.commands.errors.CommandNotFound: Command "&asciify" is not found
Ignoring exception in command None:
discord.ext.commands.errors.CommandNotFound: Command "&asciify" is not found
Ignoring exception in command None:
discord.ext.commands.errors.CommandNotFound: Command "&asciify" is not found
Ignoring exception in command None:
discord.ext.commands.errors.CommandNotFound: Command "&genascii" is not found
Ignoring exception in command None:
discord.ext.commands.errors.CommandNotFound: Command "&genascii" is not found
Vérification de la base de donnée...

Suppression de la commande help...
Effectué!

Génération des modules logs...
logs/messageEdit.py
Lancement du module messageEdit
logs/voiceConnection.py
Lancement du module voiceConnection
logs/guildChannelCreate.py
Lancement du module guildChannelCreate
logs/guildMemberJoin.py
Lancement du module guildMemberJoin
logs/guildRoleDelete.py
Lancement du module guildRoleDelete
logs/guildChannelDelete.py
Lancement du module guildChannelDelete
logs/messageAddReaction.py
Lancement du module messageAddReaction
logs/guildUserUpdate.py
Lancement du module guildUserUpdate
logs/voiceUpdate.py
Lancement du module voiceUpdate
logs/voiceSelfUpdate.py
Lancement du module voiceSelfUpdate
logs/messageRemoveReaction.py
Lancement du module messageRemoveReaction
logs/messageCreate.py
Lancement du module messageCreate
logs/guildRoleCreate.py
Lancement du module guildRoleCreate
logs/guildMemberLeave.py
Lancement du module guildMemberLeave
logs/messageDelete.py
Lancement du module messageDelete
logs/voiceSwitch.py
Lancement du module voiceSwitch
logs/guildMemberUpdate.py
Lancement du module guildMemberUpdate

Génération des modules commandes...
Lancement du module help_command
Lancement du module administration
Lancement du module utilitaire
Lancement du module moderation

Lancement du bot...
UMMBOT est prêt!
Lien d'invitation: https://discord.com/oauth2/authorize?client_id=677213520529457152&scope=bot&permissions=8

Pour inviter UMMBot, veillez copier ce lien et mettre au bot la permission administrateur.
Une fois rejoint, veillez déplacer le rôle UMMBot tout en haut de la liste des rôles.
En cas de problème, veillez contacter Bretzel_#2246.
Ignoring exception in command genascii:
Traceback (most recent call last):
  File "/usr/local/lib/python3.8/dist-packages/discord/ext/commands/core.py", line 85, in wrapped
    ret = await coro(*args, **kwargs)
  File "/root/bot/UMMBOT/cogs/utilitaire.py", line 19, in genascii
    await GenAscii(self.client).genascii(ctx, *args)
  File "/root/bot/UMMBOT/utils/ascii_gif_gen.py", line 173, in genascii
    await send_image(ctx, imgs, loop, executor)
  File "/root/bot/UMMBOT/utils/ascii_gif_gen.py", line 92, in send_image
    await ctx.send(file=discord.File(fp=image_binary, filename="asciify.gif"))
  File "/usr/local/lib/python3.8/dist-packages/discord/abc.py", line 886, in send
    data = await state.http.send_files(channel.id, files=[file], allowed_mentions=allowed_mentions,
  File "/usr/local/lib/python3.8/dist-packages/discord/http.py", line 245, in request
    raise HTTPException(r, data)
discord.errors.HTTPException: 413 Payload Too Large (error code: 40005): Request entity too large

The above exception was the direct cause of the following exception:

Traceback (most recent call last):
  File "/usr/local/lib/python3.8/dist-packages/discord/ext/commands/bot.py", line 903, in invoke
    await ctx.command.invoke(ctx)
  File "/usr/local/lib/python3.8/dist-packages/discord/ext/commands/core.py", line 859, in invoke
    await injected(*ctx.args, **ctx.kwargs)
  File "/usr/local/lib/python3.8/dist-packages/discord/ext/commands/core.py", line 94, in wrapped
    raise CommandInvokeError(exc) from exc
discord.ext.commands.errors.CommandInvokeError: Command raised an exception: HTTPException: 413 Payload Too Large (error code: 40005): Request entity too large
Ignoring exception in command genascii:
Traceback (most recent call last):
  File "/usr/local/lib/python3.8/dist-packages/discord/ext/commands/core.py", line 85, in wrapped
    ret = await coro(*args, **kwargs)
  File "/root/bot/UMMBOT/cogs/utilitaire.py", line 19, in genascii
    await GenAscii(self.client).genascii(ctx, *args)
  File "/root/bot/UMMBOT/utils/ascii_gif_gen.py", line 173, in genascii
    await send_image(ctx, imgs, loop, executor)
  File "/root/bot/UMMBOT/utils/ascii_gif_gen.py", line 92, in send_image
    await ctx.send(file=discord.File(fp=image_binary, filename="asciify.gif"))
  File "/usr/local/lib/python3.8/dist-packages/discord/abc.py", line 886, in send
    data = await state.http.send_files(channel.id, files=[file], allowed_mentions=allowed_mentions,
  File "/usr/local/lib/python3.8/dist-packages/discord/http.py", line 245, in request
    raise HTTPException(r, data)
discord.errors.HTTPException: 413 Payload Too Large (error code: 40005): Request entity too large

The above exception was the direct cause of the following exception:

Traceback (most recent call last):
  File "/usr/local/lib/python3.8/dist-packages/discord/ext/commands/bot.py", line 903, in invoke
    await ctx.command.invoke(ctx)
  File "/usr/local/lib/python3.8/dist-packages/discord/ext/commands/core.py", line 859, in invoke
    await injected(*ctx.args, **ctx.kwargs)
  File "/usr/local/lib/python3.8/dist-packages/discord/ext/commands/core.py", line 94, in wrapped
    raise CommandInvokeError(exc) from exc
discord.ext.commands.errors.CommandInvokeError: Command raised an exception: HTTPException: 413 Payload Too Large (error code: 40005): Request entity too large
Vérification de la base de donnée...

Suppression de la commande help...
Effectué!

Génération des modules logs...
logs/messageEdit.py
Lancement du module messageEdit
logs/voiceConnection.py
Lancement du module voiceConnection
logs/guildChannelCreate.py
Lancement du module guildChannelCreate
logs/guildMemberJoin.py
Lancement du module guildMemberJoin
logs/guildRoleDelete.py
Lancement du module guildRoleDelete
logs/guildChannelDelete.py
Lancement du module guildChannelDelete
logs/messageAddReaction.py
Lancement du module messageAddReaction
logs/guildUserUpdate.py
Lancement du module guildUserUpdate
logs/voiceUpdate.py
Lancement du module voiceUpdate
logs/voiceSelfUpdate.py
Lancement du module voiceSelfUpdate
logs/messageRemoveReaction.py
Lancement du module messageRemoveReaction
logs/messageCreate.py
Lancement du module messageCreate
logs/guildRoleCreate.py
Lancement du module guildRoleCreate
logs/guildMemberLeave.py
Lancement du module guildMemberLeave
logs/messageDelete.py
Lancement du module messageDelete
logs/voiceSwitch.py
Lancement du module voiceSwitch
logs/guildMemberUpdate.py
Lancement du module guildMemberUpdate

Génération des modules commandes...
Lancement du module help_command
Lancement du module administration
Lancement du module utilitaire
Lancement du module moderation

Lancement du bot...
UMMBOT est prêt!
Lien d'invitation: https://discord.com/oauth2/authorize?client_id=677213520529457152&scope=bot&permissions=8

Pour inviter UMMBot, veillez copier ce lien et mettre au bot la permission administrateur.
Une fois rejoint, veillez déplacer le rôle UMMBot tout en haut de la liste des rôles.
En cas de problème, veillez contacter Bretzel_#2246.
72
71
70
69
68
67
66
65
64
63
62
61
60
59
58
57
56
55
54
53
52
51
50
49
48
47
46
45
44
43
42
41
40
39
38
37
36
35
34
33
32
31
30
29
28
27
26
25
24
23
22
21
20
19
18
17
16
15
14
13
12
11
10
9
8
7
6
5
4
3
2
1
72
71
70
69
68
67
66
65
64
63
62
61
60
59
58
57
56
55
54
53
52
51
50
49
48
47
46
45
44
43
42
41
40
39
38
37
36
35
34
33
32
31
30
29
28
27
26
25
24
23
22
21
20
19
18
17
16
15
14
13
12
11
10
9
8
7
6
5
4
3
2
1
Ignoring exception in command genascii:
Traceback (most recent call last):
  File "/usr/local/lib/python3.8/dist-packages/discord/ext/commands/core.py", line 85, in wrapped
    ret = await coro(*args, **kwargs)
  File "/root/bot/UMMBOT/cogs/utilitaire.py", line 19, in genascii
    await GenAscii(self.client).genascii(ctx, *args)
  File "/usr/local/lib/python3.8/dist-packages/discord/ext/commands/core.py", line 374, in __call__
    return await self.callback(*args, **kwargs)
  File "/root/bot/UMMBOT/utils/ascii_gif_gen.py", line 99, in genascii
    if not ctx.message.attachments:
AttributeError: 'str' object has no attribute 'message'

The above exception was the direct cause of the following exception:

Traceback (most recent call last):
  File "/usr/local/lib/python3.8/dist-packages/discord/ext/commands/bot.py", line 903, in invoke
    await ctx.command.invoke(ctx)
  File "/usr/local/lib/python3.8/dist-packages/discord/ext/commands/core.py", line 859, in invoke
    await injected(*ctx.args, **ctx.kwargs)
  File "/usr/local/lib/python3.8/dist-packages/discord/ext/commands/core.py", line 94, in wrapped
    raise CommandInvokeError(exc) from exc
discord.ext.commands.errors.CommandInvokeError: Command raised an exception: AttributeError: 'str' object has no attribute 'message'
2021-02-02 22:34:48,821 - WARNING - We are being rate limited. Retrying in 0.10 seconds. Handled under the bucket "806284852130742293:None:/channels/{channel_id}/messages/{message_id}/reactions/{emoji}/@me"
Ignoring exception in command genascii:
Traceback (most recent call last):
  File "/usr/local/lib/python3.8/dist-packages/discord/ext/commands/core.py", line 85, in wrapped
    ret = await coro(*args, **kwargs)
  File "/root/bot/UMMBOT/cogs/utilitaire.py", line 19, in genascii
    await GenAscii(self.client).genascii(ctx, *args)
  File "/usr/local/lib/python3.8/dist-packages/discord/ext/commands/core.py", line 374, in __call__
    return await self.callback(*args, **kwargs)
TypeError: genascii() missing 1 required positional argument: 'ctx'

The above exception was the direct cause of the following exception:

Traceback (most recent call last):
  File "/usr/local/lib/python3.8/dist-packages/discord/ext/commands/bot.py", line 903, in invoke
    await ctx.command.invoke(ctx)
  File "/usr/local/lib/python3.8/dist-packages/discord/ext/commands/core.py", line 859, in invoke
    await injected(*ctx.args, **ctx.kwargs)
  File "/usr/local/lib/python3.8/dist-packages/discord/ext/commands/core.py", line 94, in wrapped
    raise CommandInvokeError(exc) from exc
discord.ext.commands.errors.CommandInvokeError: Command raised an exception: TypeError: genascii() missing 1 required positional argument: 'ctx'
Ignoring exception in command genascii:
Traceback (most recent call last):
  File "/usr/local/lib/python3.8/dist-packages/discord/ext/commands/core.py", line 85, in wrapped
    ret = await coro(*args, **kwargs)
  File "/root/bot/UMMBOT/cogs/utilitaire.py", line 19, in genascii
    await GenAscii(self.client).genascii(ctx, *args)
  File "/usr/local/lib/python3.8/dist-packages/discord/ext/commands/core.py", line 374, in __call__
    return await self.callback(*args, **kwargs)
TypeError: genascii() missing 1 required positional argument: 'ctx'

The above exception was the direct cause of the following exception:

Traceback (most recent call last):
  File "/usr/local/lib/python3.8/dist-packages/discord/ext/commands/bot.py", line 903, in invoke
    await ctx.command.invoke(ctx)
  File "/usr/local/lib/python3.8/dist-packages/discord/ext/commands/core.py", line 859, in invoke
    await injected(*ctx.args, **ctx.kwargs)
  File "/usr/local/lib/python3.8/dist-packages/discord/ext/commands/core.py", line 94, in wrapped
    raise CommandInvokeError(exc) from exc
discord.ext.commands.errors.CommandInvokeError: Command raised an exception: TypeError: genascii() missing 1 required positional argument: 'ctx'
Ignoring exception in command genascii:
Traceback (most recent call last):
  File "/usr/local/lib/python3.8/dist-packages/discord/ext/commands/core.py", line 85, in wrapped
    ret = await coro(*args, **kwargs)
  File "/root/bot/UMMBOT/cogs/utilitaire.py", line 19, in genascii
    await GenAscii(self.client).genascii(ctx, *args)
  File "/usr/local/lib/python3.8/dist-packages/discord/ext/commands/core.py", line 374, in __call__
    return await self.callback(*args, **kwargs)
TypeError: genascii() missing 1 required positional argument: 'ctx'

The above exception was the direct cause of the following exception:

Traceback (most recent call last):
  File "/usr/local/lib/python3.8/dist-packages/discord/ext/commands/bot.py", line 903, in invoke
    await ctx.command.invoke(ctx)
  File "/usr/local/lib/python3.8/dist-packages/discord/ext/commands/core.py", line 859, in invoke
    await injected(*ctx.args, **ctx.kwargs)
  File "/usr/local/lib/python3.8/dist-packages/discord/ext/commands/core.py", line 94, in wrapped
    raise CommandInvokeError(exc) from exc
discord.ext.commands.errors.CommandInvokeError: Command raised an exception: TypeError: genascii() missing 1 required positional argument: 'ctx'
Ignoring exception in command genascii:
Traceback (most recent call last):
  File "/usr/local/lib/python3.8/dist-packages/discord/ext/commands/core.py", line 85, in wrapped
    ret = await coro(*args, **kwargs)
  File "/root/bot/UMMBOT/cogs/utilitaire.py", line 19, in genascii
    await GenAscii(self.client).genascii(ctx, *args)
  File "/usr/local/lib/python3.8/dist-packages/discord/ext/commands/core.py", line 374, in __call__
    return await self.callback(*args, **kwargs)
TypeError: genascii() missing 1 required positional argument: 'ctx'

The above exception was the direct cause of the following exception:

Traceback (most recent call last):
  File "/usr/local/lib/python3.8/dist-packages/discord/ext/commands/bot.py", line 903, in invoke
    await ctx.command.invoke(ctx)
  File "/usr/local/lib/python3.8/dist-packages/discord/ext/commands/core.py", line 859, in invoke
    await injected(*ctx.args, **ctx.kwargs)
  File "/usr/local/lib/python3.8/dist-packages/discord/ext/commands/core.py", line 94, in wrapped
    raise CommandInvokeError(exc) from exc
discord.ext.commands.errors.CommandInvokeError: Command raised an exception: TypeError: genascii() missing 1 required positional argument: 'ctx'
Ignoring exception in command None:
discord.ext.commands.errors.CommandNotFound: Command "&genascii" is not found
Ignoring exception in command None:
discord.ext.commands.errors.CommandNotFound: Command "&genascii" is not found
Vérification de la base de donnée...

Suppression de la commande help...
Effectué!

Génération des modules logs...
logs/messageEdit.py
Lancement du module messageEdit
logs/voiceConnection.py
Lancement du module voiceConnection
logs/guildChannelCreate.py
Lancement du module guildChannelCreate
logs/guildMemberJoin.py
Lancement du module guildMemberJoin
logs/guildRoleDelete.py
Lancement du module guildRoleDelete
logs/guildChannelDelete.py
Lancement du module guildChannelDelete
logs/messageAddReaction.py
Lancement du module messageAddReaction
logs/guildUserUpdate.py
Lancement du module guildUserUpdate
logs/voiceUpdate.py
Lancement du module voiceUpdate
logs/voiceSelfUpdate.py
Lancement du module voiceSelfUpdate
logs/messageRemoveReaction.py
Lancement du module messageRemoveReaction
logs/messageCreate.py
Lancement du module messageCreate
logs/guildRoleCreate.py
Lancement du module guildRoleCreate
logs/guildMemberLeave.py
Lancement du module guildMemberLeave
logs/messageDelete.py
Lancement du module messageDelete
logs/voiceSwitch.py
Lancement du module voiceSwitch
logs/guildMemberUpdate.py
Lancement du module guildMemberUpdate

Génération des modules commandes...
Lancement du module help_command
Lancement du module administration
Lancement du module utilitaire
Lancement du module moderation

Lancement du bot...
UMMBOT est prêt!
Lien d'invitation: https://discord.com/oauth2/authorize?client_id=677213520529457152&scope=bot&permissions=8

Pour inviter UMMBot, veillez copier ce lien et mettre au bot la permission administrateur.
Une fois rejoint, veillez déplacer le rôle UMMBot tout en haut de la liste des rôles.
En cas de problème, veillez contacter Bretzel_#2246.
2021-02-03 05:02:07,365 - WARNING - Can't keep up, shard ID None websocket is 11.9s behind.
Ignoring exception in command None:
discord.ext.commands.errors.CommandNotFound: Command "&ascii_fonts" is not found
Ignoring exception in command None:
discord.ext.commands.errors.CommandNotFound: Command "&help" is not found
Ignoring exception in command None:
discord.ext.commands.errors.CommandNotFound: Command "&help" is not found
Ignoring exception in command None:
discord.ext.commands.errors.CommandNotFound: Command "&ascii_fonts" is not found
Ignoring exception in command None:
discord.ext.commands.errors.CommandNotFound: Command "&ascii" is not found
Ignoring exception in command None:
discord.ext.commands.errors.CommandNotFound: Command "&ascii" is not found
Ignoring exception in command None:
discord.ext.commands.errors.CommandNotFound: Command "&ascii" is not found
Ignoring exception in command None:
discord.ext.commands.errors.CommandNotFound: Command "&ascii" is not found
Ignoring exception in command None:
discord.ext.commands.errors.CommandNotFound: Command "&ascii" is not found
Ignoring exception in command None:
discord.ext.commands.errors.CommandNotFound: Command "&ascii" is not found
Ignoring exception in command None:
discord.ext.commands.errors.CommandNotFound: Command "&ascii" is not found
Ignoring exception in command None:
discord.ext.commands.errors.CommandNotFound: Command "&ascii" is not found
Ignoring exception in command None:
discord.ext.commands.errors.CommandNotFound: Command "&ascii" is not found
Ignoring exception in command None:
discord.ext.commands.errors.CommandNotFound: Command "&ascii" is not found
Ignoring exception in command None:
discord.ext.commands.errors.CommandNotFound: Command "&ascii" is not found
Ignoring exception in command None:
discord.ext.commands.errors.CommandNotFound: Command "&ascii" is not found
Ignoring exception in command None:
discord.ext.commands.errors.CommandNotFound: Command "&gascii" is not found
Ignoring exception in command None:
discord.ext.commands.errors.CommandNotFound: Command "&gascii" is not found
Ignoring exception in command None:
discord.ext.commands.errors.CommandNotFound: Command "&gascii" is not found
Ignoring exception in command None:
discord.ext.commands.errors.CommandNotFound: Command "&gascii" is not found
Ignoring exception in command None:
discord.ext.commands.errors.CommandNotFound: Command "&gascii" is not found
Ignoring exception in command None:
discord.ext.commands.errors.CommandNotFound: Command "&gascii" is not found
Ignoring exception in command None:
discord.ext.commands.errors.CommandNotFound: Command "&gascii" is not found
Ignoring exception in command None:
discord.ext.commands.errors.CommandNotFound: Command "&gascii" is not found
Ignoring exception in command None:
discord.ext.commands.errors.CommandNotFound: Command "&gascii" is not found
Ignoring exception in command None:
discord.ext.commands.errors.CommandNotFound: Command "&genascii" is not found
Ignoring exception in command None:
discord.ext.commands.errors.CommandNotFound: Command "&asciify" is not found
Ignoring exception in command None:
discord.ext.commands.errors.CommandNotFound: Command "&asciify" is not found
Ignoring exception in command None:
discord.ext.commands.errors.CommandNotFound: Command "&asciify" is not found
Ignoring exception in command None:
discord.ext.commands.errors.CommandNotFound: Command "&asciify" is not found
Ignoring exception in command None:
discord.ext.commands.errors.CommandNotFound: Command "&asciify" is not found
Ignoring exception in command None:
discord.ext.commands.errors.CommandNotFound: Command "&asciify" is not found
Ignoring exception in command None:
discord.ext.commands.errors.CommandNotFound: Command "&asciify" is not found
Ignoring exception in command None:
discord.ext.commands.errors.CommandNotFound: Command "&asciify" is not found
Ignoring exception in command None:
discord.ext.commands.errors.CommandNotFound: Command "&asciify" is not found
Vérification de la base de donnée...

Suppression de la commande help...
Effectué!

Génération des modules logs...
logs/messageEdit.py
Lancement du module messageEdit
logs/voiceConnection.py
Lancement du module voiceConnection
logs/guildChannelCreate.py
Lancement du module guildChannelCreate
logs/guildMemberJoin.py
Lancement du module guildMemberJoin
logs/guildRoleDelete.py
Lancement du module guildRoleDelete
logs/guildChannelDelete.py
Lancement du module guildChannelDelete
logs/messageAddReaction.py
Lancement du module messageAddReaction
logs/guildUserUpdate.py
Lancement du module guildUserUpdate
logs/voiceUpdate.py
Lancement du module voiceUpdate
logs/voiceSelfUpdate.py
Lancement du module voiceSelfUpdate
logs/messageRemoveReaction.py
Lancement du module messageRemoveReaction
logs/messageCreate.py
Lancement du module messageCreate
logs/guildRoleCreate.py
Lancement du module guildRoleCreate
logs/guildMemberLeave.py
Lancement du module guildMemberLeave
logs/messageDelete.py
Lancement du module messageDelete
logs/voiceSwitch.py
Lancement du module voiceSwitch
logs/guildMemberUpdate.py
Lancement du module guildMemberUpdate

Génération des modules commandes...
Lancement du module help_command
Lancement du module administration
Lancement du module utilitaire
Lancement du module moderation

Lancement du bot...
UMMBOT est prêt!
Lien d'invitation: https://discord.com/oauth2/authorize?client_id=677213520529457152&scope=bot&permissions=8

Pour inviter UMMBot, veillez copier ce lien et mettre au bot la permission administrateur.
Une fois rejoint, veillez déplacer le rôle UMMBot tout en haut de la liste des rôles.
En cas de problème, veillez contacter Bretzel_#2246.
(72, 101)
(70, 99)
(68, 96)
(66, 93)
(64, 90)
(62, 87)
(60, 84)
(58, 82)
(56, 79)
(54, 76)
(52, 73)
(50, 70)
(48, 67)
(46, 65)
(44, 62)
(42, 59)
(40, 56)
(38, 53)
(36, 50)
(34, 48)
(32, 45)
(30, 42)
(28, 39)
(26, 36)
(24, 33)
(22, 31)
(20, 28)
(18, 25)
(16, 22)
(14, 19)
(12, 16)
(10, 14)
(8, 11)
(6, 8)
(4, 5)
(2, 2)
(72, 76)
(71, 75)
(70, 74)
(69, 73)
(68, 72)
(67, 71)
(66, 69)
(65, 68)
(64, 67)
(63, 66)
(62, 65)
(61, 64)
(60, 63)
(59, 62)
(58, 61)
(57, 60)
(56, 59)
(55, 58)
(54, 57)
(53, 56)
(52, 55)
(51, 54)
(50, 53)
(49, 51)
(48, 50)
(47, 49)
(46, 48)
(45, 47)
(44, 46)
(43, 45)
(42, 44)
(41, 43)
(40, 42)
(39, 41)
(38, 40)
(37, 39)
(36, 38)
(35, 37)
(34, 36)
(33, 34)
(32, 33)
(31, 32)
(30, 31)
(29, 30)
(28, 29)
(27, 28)
(26, 27)
(25, 26)
(24, 25)
(23, 24)
(22, 23)
(21, 22)
(20, 21)
(19, 20)
(18, 19)
(17, 18)
(16, 16)
(15, 15)
(14, 14)
(13, 13)
(12, 12)
(11, 11)
(10, 10)
(9, 9)
(8, 8)
(7, 7)
(6, 6)
(5, 5)
(4, 4)
(3, 3)
(2, 2)
(1, 1)
(72, 101)
(71, 100)
(70, 99)
(69, 97)
(68, 96)
(67, 94)
(66, 93)
(65, 91)
(64, 90)
(63, 89)
(62, 87)
(61, 86)
(60, 84)
(59, 83)
(58, 82)
(57, 80)
(56, 79)
(55, 77)
(54, 76)
(53, 74)
(52, 73)
(51, 72)
(50, 70)
(49, 69)
(48, 67)
(47, 66)
(46, 65)
(45, 63)
(44, 62)
(43, 60)
(42, 59)
(41, 58)
(40, 56)
(39, 55)
(38, 53)
(37, 52)
(36, 50)
(35, 49)
(34, 48)
(33, 46)
(32, 45)
(31, 43)
(30, 42)
(29, 41)
(28, 39)
(27, 38)
(26, 36)
(25, 35)
(24, 33)
(23, 32)
(22, 31)
(21, 29)
(20, 28)
(19, 26)
(18, 25)
(17, 24)
(16, 22)
(15, 21)
(14, 19)
(13, 18)
(12, 16)
(11, 15)
(10, 14)
(9, 12)
(8, 11)
(7, 9)
(6, 8)
(5, 7)
(4, 5)
(3, 4)
(2, 2)
(1, 1)
Vérification de la base de donnée...

Suppression de la commande help...
Effectué!

Génération des modules logs...
logs/messageEdit.py
Lancement du module messageEdit
logs/voiceConnection.py
Lancement du module voiceConnection
logs/guildChannelCreate.py
Lancement du module guildChannelCreate
logs/guildMemberJoin.py
Lancement du module guildMemberJoin
logs/guildRoleDelete.py
Lancement du module guildRoleDelete
logs/guildChannelDelete.py
Lancement du module guildChannelDelete
logs/messageAddReaction.py
Lancement du module messageAddReaction
logs/guildUserUpdate.py
Lancement du module guildUserUpdate
logs/voiceUpdate.py
Lancement du module voiceUpdate
logs/voiceSelfUpdate.py
Lancement du module voiceSelfUpdate
logs/messageRemoveReaction.py
Lancement du module messageRemoveReaction
logs/messageCreate.py
Lancement du module messageCreate
logs/guildRoleCreate.py
Lancement du module guildRoleCreate
logs/guildMemberLeave.py
Lancement du module guildMemberLeave
logs/messageDelete.py
Lancement du module messageDelete
logs/voiceSwitch.py
Lancement du module voiceSwitch
logs/guildMemberUpdate.py
Lancement du module guildMemberUpdate

Génération des modules commandes...
Lancement du module help_command
Lancement du module administration
Lancement du module utilitaire
Traceback (most recent call last):
  File "/usr/local/lib/python3.8/dist-packages/discord/ext/commands/bot.py", line 607, in _load_from_module_spec
    spec.loader.exec_module(lib)
  File "<frozen importlib._bootstrap_external>", line 783, in exec_module
  File "<frozen importlib._bootstrap>", line 219, in _call_with_frames_removed
  File "/root/bot/UMMBOT/cogs/utilitaire.py", line 5, in <module>
    from utils.gascii import Gascii
ModuleNotFoundError: No module named 'utils.gascii'

The above exception was the direct cause of the following exception:

Traceback (most recent call last):
  File "UMM.py", line 79, in <module>
    bot.start_bot(TOKEN)
  File "UMM.py", line 57, in start_bot
    self.load_commands()
  File "UMM.py", line 46, in load_commands
    self.load_extension(f'cogs.{files}')
  File "/usr/local/lib/python3.8/dist-packages/discord/ext/commands/bot.py", line 664, in load_extension
    self._load_from_module_spec(spec, name)
  File "/usr/local/lib/python3.8/dist-packages/discord/ext/commands/bot.py", line 610, in _load_from_module_spec
    raise errors.ExtensionFailed(key, e) from e
discord.ext.commands.errors.ExtensionFailed: Extension 'cogs.utilitaire' raised an error: ModuleNotFoundError: No module named 'utils.gascii'
Ignoring exception in command ascii_fonts:
Traceback (most recent call last):
  File "/usr/local/lib/python3.8/dist-packages/discord/ext/commands/core.py", line 85, in wrapped
    ret = await coro(*args, **kwargs)
  File "/root/bot/UMMBOT/cogs/utilitaire.py", line 41, in ascii_fonts
    await Ascii(self.client).ascii_fonts(ctx, *args)
  File "/root/bot/UMMBOT/utils/ascii_text.py", line 31, in ascii_fonts
    await channel.send(
  File "/usr/local/lib/python3.8/dist-packages/discord/abc.py", line 904, in send
    data = await state.http.send_message(channel.id, content, tts=tts, embed=embed,
  File "/usr/local/lib/python3.8/dist-packages/discord/http.py", line 245, in request
    raise HTTPException(r, data)
discord.errors.HTTPException: 400 Bad Request (error code: 50035): Invalid Form Body
In content: Must be 2000 or fewer in length.

The above exception was the direct cause of the following exception:

Traceback (most recent call last):
  File "/usr/local/lib/python3.8/dist-packages/discord/ext/commands/bot.py", line 903, in invoke
    await ctx.command.invoke(ctx)
  File "/usr/local/lib/python3.8/dist-packages/discord/ext/commands/core.py", line 859, in invoke
    await injected(*ctx.args, **ctx.kwargs)
  File "/usr/local/lib/python3.8/dist-packages/discord/ext/commands/core.py", line 94, in wrapped
    raise CommandInvokeError(exc) from exc
discord.ext.commands.errors.CommandInvokeError: Command raised an exception: HTTPException: 400 Bad Request (error code: 50035): Invalid Form Body
In content: Must be 2000 or fewer in length.
Ignoring exception in command ascii_fonts:
Traceback (most recent call last):
  File "/usr/local/lib/python3.8/dist-packages/discord/ext/commands/core.py", line 85, in wrapped
    ret = await coro(*args, **kwargs)
  File "/root/bot/UMMBOT/cogs/utilitaire.py", line 41, in ascii_fonts
    await Ascii(self.client).ascii_fonts(ctx, *args)
  File "/root/bot/UMMBOT/utils/ascii_text.py", line 31, in ascii_fonts
    await channel.send(
  File "/usr/local/lib/python3.8/dist-packages/discord/abc.py", line 904, in send
    data = await state.http.send_message(channel.id, content, tts=tts, embed=embed,
  File "/usr/local/lib/python3.8/dist-packages/discord/http.py", line 245, in request
    raise HTTPException(r, data)
discord.errors.HTTPException: 400 Bad Request (error code: 50035): Invalid Form Body
In content: Must be 2000 or fewer in length.

The above exception was the direct cause of the following exception:

Traceback (most recent call last):
  File "/usr/local/lib/python3.8/dist-packages/discord/ext/commands/bot.py", line 903, in invoke
    await ctx.command.invoke(ctx)
  File "/usr/local/lib/python3.8/dist-packages/discord/ext/commands/core.py", line 859, in invoke
    await injected(*ctx.args, **ctx.kwargs)
  File "/usr/local/lib/python3.8/dist-packages/discord/ext/commands/core.py", line 94, in wrapped
    raise CommandInvokeError(exc) from exc
discord.ext.commands.errors.CommandInvokeError: Command raised an exception: HTTPException: 400 Bad Request (error code: 50035): Invalid Form Body
In content: Must be 2000 or fewer in length.
Vérification de la base de donnée...

Suppression de la commande help...
Effectué!

Génération des modules logs...
logs/messageEdit.py
Lancement du module messageEdit
logs/voiceConnection.py
Lancement du module voiceConnection
logs/guildChannelCreate.py
Lancement du module guildChannelCreate
logs/guildMemberJoin.py
Lancement du module guildMemberJoin
logs/guildRoleDelete.py
Lancement du module guildRoleDelete
logs/guildChannelDelete.py
Lancement du module guildChannelDelete
logs/messageAddReaction.py
Lancement du module messageAddReaction
logs/guildUserUpdate.py
Lancement du module guildUserUpdate
logs/voiceUpdate.py
Lancement du module voiceUpdate
logs/voiceSelfUpdate.py
Lancement du module voiceSelfUpdate
logs/messageRemoveReaction.py
Lancement du module messageRemoveReaction
logs/messageCreate.py
Lancement du module messageCreate
logs/guildRoleCreate.py
Lancement du module guildRoleCreate
logs/guildMemberLeave.py
Lancement du module guildMemberLeave
logs/messageDelete.py
Lancement du module messageDelete
logs/voiceSwitch.py
Lancement du module voiceSwitch
logs/guildMemberUpdate.py
Lancement du module guildMemberUpdate

Génération des modules commandes...
Lancement du module help_command
Lancement du module administration
Lancement du module utilitaire
Lancement du module moderation

Lancement du bot...
UMMBOT est prêt!
Lien d'invitation: https://discord.com/oauth2/authorize?client_id=677213520529457152&scope=bot&permissions=8

Pour inviter UMMBot, veillez copier ce lien et mettre au bot la permission administrateur.
Une fois rejoint, veillez déplacer le rôle UMMBot tout en haut de la liste des rôles.
En cas de problème, veillez contacter Bretzel_#2246.
Ignoring exception in command ascii_fonts:
Traceback (most recent call last):
  File "/usr/local/lib/python3.8/dist-packages/discord/ext/commands/core.py", line 85, in wrapped
    ret = await coro(*args, **kwargs)
  File "/root/bot/UMMBOT/cogs/utilitaire.py", line 41, in ascii_fonts
    await Ascii(self.client).ascii_fonts(ctx, *args)
  File "/root/bot/UMMBOT/utils/ascii_text.py", line 32, in ascii_fonts
    await channel.send(
  File "/usr/local/lib/python3.8/dist-packages/discord/abc.py", line 904, in send
    data = await state.http.send_message(channel.id, content, tts=tts, embed=embed,
  File "/usr/local/lib/python3.8/dist-packages/discord/http.py", line 245, in request
    raise HTTPException(r, data)
discord.errors.HTTPException: 400 Bad Request (error code: 50035): Invalid Form Body
In content: Must be 2000 or fewer in length.

The above exception was the direct cause of the following exception:

Traceback (most recent call last):
  File "/usr/local/lib/python3.8/dist-packages/discord/ext/commands/bot.py", line 903, in invoke
    await ctx.command.invoke(ctx)
  File "/usr/local/lib/python3.8/dist-packages/discord/ext/commands/core.py", line 859, in invoke
    await injected(*ctx.args, **ctx.kwargs)
  File "/usr/local/lib/python3.8/dist-packages/discord/ext/commands/core.py", line 94, in wrapped
    raise CommandInvokeError(exc) from exc
discord.ext.commands.errors.CommandInvokeError: Command raised an exception: HTTPException: 400 Bad Request (error code: 50035): Invalid Form Body
In content: Must be 2000 or fewer in length.
Ignoring exception in command ascii_fonts:
Traceback (most recent call last):
  File "/usr/local/lib/python3.8/dist-packages/discord/ext/commands/core.py", line 85, in wrapped
    ret = await coro(*args, **kwargs)
  File "/root/bot/UMMBOT/cogs/utilitaire.py", line 41, in ascii_fonts
    await Ascii(self.client).ascii_fonts(ctx, *args)
  File "/root/bot/UMMBOT/utils/ascii_text.py", line 32, in ascii_fonts
    await channel.send(
  File "/usr/local/lib/python3.8/dist-packages/discord/abc.py", line 904, in send
    data = await state.http.send_message(channel.id, content, tts=tts, embed=embed,
  File "/usr/local/lib/python3.8/dist-packages/discord/http.py", line 245, in request
    raise HTTPException(r, data)
discord.errors.HTTPException: 400 Bad Request (error code: 50035): Invalid Form Body
In content: Must be 2000 or fewer in length.

The above exception was the direct cause of the following exception:

Traceback (most recent call last):
  File "/usr/local/lib/python3.8/dist-packages/discord/ext/commands/bot.py", line 903, in invoke
    await ctx.command.invoke(ctx)
  File "/usr/local/lib/python3.8/dist-packages/discord/ext/commands/core.py", line 859, in invoke
    await injected(*ctx.args, **ctx.kwargs)
  File "/usr/local/lib/python3.8/dist-packages/discord/ext/commands/core.py", line 94, in wrapped
    raise CommandInvokeError(exc) from exc
discord.ext.commands.errors.CommandInvokeError: Command raised an exception: HTTPException: 400 Bad Request (error code: 50035): Invalid Form Body
In content: Must be 2000 or fewer in length.
Ignoring exception in command ascii_fonts:
Traceback (most recent call last):
  File "/usr/local/lib/python3.8/dist-packages/discord/ext/commands/core.py", line 85, in wrapped
    ret = await coro(*args, **kwargs)
  File "/root/bot/UMMBOT/cogs/utilitaire.py", line 41, in ascii_fonts
    await Ascii(self.client).ascii_fonts(ctx, *args)
  File "/root/bot/UMMBOT/utils/ascii_text.py", line 32, in ascii_fonts
    await channel.send(
  File "/usr/local/lib/python3.8/dist-packages/discord/abc.py", line 904, in send
    data = await state.http.send_message(channel.id, content, tts=tts, embed=embed,
  File "/usr/local/lib/python3.8/dist-packages/discord/http.py", line 245, in request
    raise HTTPException(r, data)
discord.errors.HTTPException: 400 Bad Request (error code: 50035): Invalid Form Body
In content: Must be 2000 or fewer in length.

The above exception was the direct cause of the following exception:

Traceback (most recent call last):
  File "/usr/local/lib/python3.8/dist-packages/discord/ext/commands/bot.py", line 903, in invoke
    await ctx.command.invoke(ctx)
  File "/usr/local/lib/python3.8/dist-packages/discord/ext/commands/core.py", line 859, in invoke
    await injected(*ctx.args, **ctx.kwargs)
  File "/usr/local/lib/python3.8/dist-packages/discord/ext/commands/core.py", line 94, in wrapped
    raise CommandInvokeError(exc) from exc
discord.ext.commands.errors.CommandInvokeError: Command raised an exception: HTTPException: 400 Bad Request (error code: 50035): Invalid Form Body
In content: Must be 2000 or fewer in length.
Ignoring exception in command ascii_fonts:
Traceback (most recent call last):
  File "/usr/local/lib/python3.8/dist-packages/discord/ext/commands/core.py", line 85, in wrapped
    ret = await coro(*args, **kwargs)
  File "/root/bot/UMMBOT/cogs/utilitaire.py", line 41, in ascii_fonts
    await Ascii(self.client).ascii_fonts(ctx, *args)
  File "/root/bot/UMMBOT/utils/ascii_text.py", line 32, in ascii_fonts
    await channel.send(
  File "/usr/local/lib/python3.8/dist-packages/discord/abc.py", line 904, in send
    data = await state.http.send_message(channel.id, content, tts=tts, embed=embed,
  File "/usr/local/lib/python3.8/dist-packages/discord/http.py", line 245, in request
    raise HTTPException(r, data)
discord.errors.HTTPException: 400 Bad Request (error code: 50035): Invalid Form Body
In content: Must be 2000 or fewer in length.

The above exception was the direct cause of the following exception:

Traceback (most recent call last):
  File "/usr/local/lib/python3.8/dist-packages/discord/ext/commands/bot.py", line 903, in invoke
    await ctx.command.invoke(ctx)
  File "/usr/local/lib/python3.8/dist-packages/discord/ext/commands/core.py", line 859, in invoke
    await injected(*ctx.args, **ctx.kwargs)
  File "/usr/local/lib/python3.8/dist-packages/discord/ext/commands/core.py", line 94, in wrapped
    raise CommandInvokeError(exc) from exc
discord.ext.commands.errors.CommandInvokeError: Command raised an exception: HTTPException: 400 Bad Request (error code: 50035): Invalid Form Body
In content: Must be 2000 or fewer in length.
Ignoring exception in command ascii_fonts:
Traceback (most recent call last):
  File "/usr/local/lib/python3.8/dist-packages/discord/ext/commands/core.py", line 85, in wrapped
    ret = await coro(*args, **kwargs)
  File "/root/bot/UMMBOT/cogs/utilitaire.py", line 41, in ascii_fonts
    await Ascii(self.client).ascii_fonts(ctx, *args)
  File "/root/bot/UMMBOT/utils/ascii_text.py", line 32, in ascii_fonts
    await channel.send(
  File "/usr/local/lib/python3.8/dist-packages/discord/abc.py", line 904, in send
    data = await state.http.send_message(channel.id, content, tts=tts, embed=embed,
  File "/usr/local/lib/python3.8/dist-packages/discord/http.py", line 245, in request
    raise HTTPException(r, data)
discord.errors.HTTPException: 400 Bad Request (error code: 50035): Invalid Form Body
In content: Must be 2000 or fewer in length.

The above exception was the direct cause of the following exception:

Traceback (most recent call last):
  File "/usr/local/lib/python3.8/dist-packages/discord/ext/commands/bot.py", line 903, in invoke
    await ctx.command.invoke(ctx)
  File "/usr/local/lib/python3.8/dist-packages/discord/ext/commands/core.py", line 859, in invoke
    await injected(*ctx.args, **ctx.kwargs)
  File "/usr/local/lib/python3.8/dist-packages/discord/ext/commands/core.py", line 94, in wrapped
    raise CommandInvokeError(exc) from exc
discord.ext.commands.errors.CommandInvokeError: Command raised an exception: HTTPException: 400 Bad Request (error code: 50035): Invalid Form Body
In content: Must be 2000 or fewer in length.
Ignoring exception in command None:
discord.ext.commands.errors.CommandNotFound: Command "&ascii_fonts" is not found
Ignoring exception in command None:
discord.ext.commands.errors.CommandNotFound: Command "&ascii_fonts" is not found
Vérification de la base de donnée...

Suppression de la commande help...
Effectué!

Génération des modules logs...
logs/messageEdit.py
Lancement du module messageEdit
logs/voiceConnection.py
Lancement du module voiceConnection
logs/guildChannelCreate.py
Lancement du module guildChannelCreate
logs/guildMemberJoin.py
Lancement du module guildMemberJoin
logs/guildRoleDelete.py
Lancement du module guildRoleDelete
logs/guildChannelDelete.py
Lancement du module guildChannelDelete
logs/messageAddReaction.py
Lancement du module messageAddReaction
logs/guildUserUpdate.py
Lancement du module guildUserUpdate
logs/voiceUpdate.py
Lancement du module voiceUpdate
logs/voiceSelfUpdate.py
Lancement du module voiceSelfUpdate
logs/messageRemoveReaction.py
Lancement du module messageRemoveReaction
logs/messageCreate.py
Lancement du module messageCreate
logs/guildRoleCreate.py
Lancement du module guildRoleCreate
logs/guildMemberLeave.py
Lancement du module guildMemberLeave
logs/messageDelete.py
Lancement du module messageDelete
logs/voiceSwitch.py
Lancement du module voiceSwitch
logs/guildMemberUpdate.py
Lancement du module guildMemberUpdate

Génération des modules commandes...
Lancement du module help_command
Lancement du module administration
Lancement du module utilitaire
Lancement du module moderation

Lancement du bot...
UMMBOT est prêt!
Lien d'invitation: https://discord.com/oauth2/authorize?client_id=677213520529457152&scope=bot&permissions=8

Pour inviter UMMBot, veillez copier ce lien et mettre au bot la permission administrateur.
Une fois rejoint, veillez déplacer le rôle UMMBot tout en haut de la liste des rôles.
En cas de problème, veillez contacter Bretzel_#2246.
/usr/local/lib/python3.8/dist-packages/pyfiglet/__init__.py
/usr/local/lib/python3.8/dist-packages/pyfiglet/__init__.py
/usr/local/lib/python3.8/dist-packages/pyfiglet/__init__.py
/usr/local/lib/python3.8/dist-packages/pyfiglet/__init__.py
/usr/local/lib/python3.8/dist-packages/pyfiglet/__init__.py
Ignoring exception in command ascii_fonts:
Traceback (most recent call last):
  File "/usr/local/lib/python3.8/dist-packages/discord/ext/commands/core.py", line 85, in wrapped
    ret = await coro(*args, **kwargs)
  File "/root/bot/UMMBOT/cogs/utilitaire.py", line 41, in ascii_fonts
    await Ascii(self.client).ascii_fonts(ctx, *args)
  File "/root/bot/UMMBOT/utils/ascii_text.py", line 33, in ascii_fonts
    await channel.send(
  File "/usr/local/lib/python3.8/dist-packages/discord/abc.py", line 904, in send
    data = await state.http.send_message(channel.id, content, tts=tts, embed=embed,
  File "/usr/local/lib/python3.8/dist-packages/discord/http.py", line 245, in request
    raise HTTPException(r, data)
discord.errors.HTTPException: 400 Bad Request (error code: 50035): Invalid Form Body
In content: Must be 2000 or fewer in length.

The above exception was the direct cause of the following exception:

Traceback (most recent call last):
  File "/usr/local/lib/python3.8/dist-packages/discord/ext/commands/bot.py", line 903, in invoke
    await ctx.command.invoke(ctx)
  File "/usr/local/lib/python3.8/dist-packages/discord/ext/commands/core.py", line 859, in invoke
    await injected(*ctx.args, **ctx.kwargs)
  File "/usr/local/lib/python3.8/dist-packages/discord/ext/commands/core.py", line 94, in wrapped
    raise CommandInvokeError(exc) from exc
discord.ext.commands.errors.CommandInvokeError: Command raised an exception: HTTPException: 400 Bad Request (error code: 50035): Invalid Form Body
In content: Must be 2000 or fewer in length.
2021-02-03 20:24:41,281 - WARNING - We are being rate limited. Retrying in 0.10 seconds. Handled under the bucket "806284852130742293:None:/channels/{channel_id}/messages/{message_id}/reactions/{emoji}/@me"
Ignoring exception in command ascii_fonts:
Traceback (most recent call last):
  File "/usr/local/lib/python3.8/dist-packages/discord/ext/commands/core.py", line 85, in wrapped
    ret = await coro(*args, **kwargs)
  File "/root/bot/UMMBOT/cogs/utilitaire.py", line 41, in ascii_fonts
    await Ascii(self.client).ascii_fonts(ctx, *args)
  File "/root/bot/UMMBOT/utils/ascii_text.py", line 33, in ascii_fonts
    await channel.send(
  File "/usr/local/lib/python3.8/dist-packages/discord/abc.py", line 904, in send
    data = await state.http.send_message(channel.id, content, tts=tts, embed=embed,
  File "/usr/local/lib/python3.8/dist-packages/discord/http.py", line 245, in request
    raise HTTPException(r, data)
discord.errors.HTTPException: 400 Bad Request (error code: 50035): Invalid Form Body
In content: Must be 2000 or fewer in length.

The above exception was the direct cause of the following exception:

Traceback (most recent call last):
  File "/usr/local/lib/python3.8/dist-packages/discord/ext/commands/bot.py", line 903, in invoke
    await ctx.command.invoke(ctx)
  File "/usr/local/lib/python3.8/dist-packages/discord/ext/commands/core.py", line 859, in invoke
    await injected(*ctx.args, **ctx.kwargs)
  File "/usr/local/lib/python3.8/dist-packages/discord/ext/commands/core.py", line 94, in wrapped
    raise CommandInvokeError(exc) from exc
discord.ext.commands.errors.CommandInvokeError: Command raised an exception: HTTPException: 400 Bad Request (error code: 50035): Invalid Form Body
In content: Must be 2000 or fewer in length.
Ignoring exception in command None:
discord.ext.commands.errors.CommandNotFound: Command "&ascii_fonts" is not found
Ignoring exception in command None:
discord.ext.commands.errors.CommandNotFound: Command "&ascii_fonts" is not found
Ignoring exception in command None:
discord.ext.commands.errors.CommandNotFound: Command "&ascii_fonts" is not found
Ignoring exception in command None:
discord.ext.commands.errors.CommandNotFound: Command "&ascii_fonts" is not found
Ignoring exception in command None:
discord.ext.commands.errors.CommandNotFound: Command "&ascii_fonts" is not found
Vérification de la base de donnée...

Suppression de la commande help...
Effectué!

Génération des modules logs...
logs/messageEdit.py
Lancement du module messageEdit
logs/voiceConnection.py
Lancement du module voiceConnection
logs/guildChannelCreate.py
Lancement du module guildChannelCreate
logs/guildMemberJoin.py
Lancement du module guildMemberJoin
logs/guildRoleDelete.py
Lancement du module guildRoleDelete
logs/guildChannelDelete.py
Lancement du module guildChannelDelete
logs/messageAddReaction.py
Lancement du module messageAddReaction
logs/guildUserUpdate.py
Lancement du module guildUserUpdate
logs/voiceUpdate.py
Lancement du module voiceUpdate
logs/voiceSelfUpdate.py
Lancement du module voiceSelfUpdate
logs/messageRemoveReaction.py
Lancement du module messageRemoveReaction
logs/messageCreate.py
Lancement du module messageCreate
logs/guildRoleCreate.py
Lancement du module guildRoleCreate
logs/guildMemberLeave.py
Lancement du module guildMemberLeave
logs/messageDelete.py
Lancement du module messageDelete
logs/voiceSwitch.py
Lancement du module voiceSwitch
logs/guildMemberUpdate.py
Lancement du module guildMemberUpdate

Génération des modules commandes...
Lancement du module help_command
Lancement du module administration
Lancement du module utilitaire
Lancement du module moderation

Lancement du bot...
UMMBOT est prêt!
Lien d'invitation: https://discord.com/oauth2/authorize?client_id=677213520529457152&scope=bot&permissions=8

Pour inviter UMMBot, veillez copier ce lien et mettre au bot la permission administrateur.
Une fois rejoint, veillez déplacer le rôle UMMBot tout en haut de la liste des rôles.
En cas de problème, veillez contacter Bretzel_#2246.
()
/usr/local/lib/python3.8/dist-packages/pyfiglet/__init__.py
()
/usr/local/lib/python3.8/dist-packages/pyfiglet/__init__.py
Ignoring exception in command ascii_fonts:
Traceback (most recent call last):
  File "/usr/local/lib/python3.8/dist-packages/discord/ext/commands/core.py", line 85, in wrapped
    ret = await coro(*args, **kwargs)
  File "/root/bot/UMMBOT/cogs/utilitaire.py", line 41, in ascii_fonts
    await Ascii(self.client).ascii_fonts(ctx, *args)
  File "/root/bot/UMMBOT/utils/ascii_text.py", line 40, in ascii_fonts
    await channel.send(
  File "/usr/local/lib/python3.8/dist-packages/discord/abc.py", line 904, in send
    data = await state.http.send_message(channel.id, content, tts=tts, embed=embed,
  File "/usr/local/lib/python3.8/dist-packages/discord/http.py", line 245, in request
    raise HTTPException(r, data)
discord.errors.HTTPException: 400 Bad Request (error code: 50035): Invalid Form Body
In content: Must be 2000 or fewer in length.

The above exception was the direct cause of the following exception:

Traceback (most recent call last):
  File "/usr/local/lib/python3.8/dist-packages/discord/ext/commands/bot.py", line 903, in invoke
    await ctx.command.invoke(ctx)
  File "/usr/local/lib/python3.8/dist-packages/discord/ext/commands/core.py", line 859, in invoke
    await injected(*ctx.args, **ctx.kwargs)
  File "/usr/local/lib/python3.8/dist-packages/discord/ext/commands/core.py", line 94, in wrapped
    raise CommandInvokeError(exc) from exc
discord.ext.commands.errors.CommandInvokeError: Command raised an exception: HTTPException: 400 Bad Request (error code: 50035): Invalid Form Body
In content: Must be 2000 or fewer in length.
Ignoring exception in command ascii_fonts:
Traceback (most recent call last):
  File "/usr/local/lib/python3.8/dist-packages/discord/ext/commands/core.py", line 85, in wrapped
    ret = await coro(*args, **kwargs)
  File "/root/bot/UMMBOT/cogs/utilitaire.py", line 41, in ascii_fonts
    await Ascii(self.client).ascii_fonts(ctx, *args)
  File "/root/bot/UMMBOT/utils/ascii_text.py", line 40, in ascii_fonts
    await channel.send(
  File "/usr/local/lib/python3.8/dist-packages/discord/abc.py", line 904, in send
    data = await state.http.send_message(channel.id, content, tts=tts, embed=embed,
  File "/usr/local/lib/python3.8/dist-packages/discord/http.py", line 245, in request
    raise HTTPException(r, data)
discord.errors.HTTPException: 400 Bad Request (error code: 50035): Invalid Form Body
In content: Must be 2000 or fewer in length.

The above exception was the direct cause of the following exception:

Traceback (most recent call last):
  File "/usr/local/lib/python3.8/dist-packages/discord/ext/commands/bot.py", line 903, in invoke
    await ctx.command.invoke(ctx)
  File "/usr/local/lib/python3.8/dist-packages/discord/ext/commands/core.py", line 859, in invoke
    await injected(*ctx.args, **ctx.kwargs)
  File "/usr/local/lib/python3.8/dist-packages/discord/ext/commands/core.py", line 94, in wrapped
    raise CommandInvokeError(exc) from exc
discord.ext.commands.errors.CommandInvokeError: Command raised an exception: HTTPException: 400 Bad Request (error code: 50035): Invalid Form Body
In content: Must be 2000 or fewer in length.
Vérification de la base de donnée...

Suppression de la commande help...
Effectué!

Génération des modules logs...
logs/messageEdit.py
Lancement du module messageEdit
logs/voiceConnection.py
Lancement du module voiceConnection
logs/guildChannelCreate.py
Lancement du module guildChannelCreate
logs/guildMemberJoin.py
Lancement du module guildMemberJoin
logs/guildRoleDelete.py
Lancement du module guildRoleDelete
logs/guildChannelDelete.py
Lancement du module guildChannelDelete
logs/messageAddReaction.py
Lancement du module messageAddReaction
logs/guildUserUpdate.py
Lancement du module guildUserUpdate
logs/voiceUpdate.py
Lancement du module voiceUpdate
logs/voiceSelfUpdate.py
Lancement du module voiceSelfUpdate
logs/messageRemoveReaction.py
Lancement du module messageRemoveReaction
logs/messageCreate.py
Lancement du module messageCreate
logs/guildRoleCreate.py
Lancement du module guildRoleCreate
logs/guildMemberLeave.py
Lancement du module guildMemberLeave
logs/messageDelete.py
Lancement du module messageDelete
logs/voiceSwitch.py
Lancement du module voiceSwitch
logs/guildMemberUpdate.py
Lancement du module guildMemberUpdate

Génération des modules commandes...
Lancement du module help_command
Lancement du module administration
Lancement du module utilitaire
Lancement du module moderation

Lancement du bot...
UMMBOT est prêt!
Lien d'invitation: https://discord.com/oauth2/authorize?client_id=677213520529457152&scope=bot&permissions=8

Pour inviter UMMBot, veillez copier ce lien et mettre au bot la permission administrateur.
Une fois rejoint, veillez déplacer le rôle UMMBot tout en haut de la liste des rôles.
En cas de problème, veillez contacter Bretzel_#2246.
Ignoring exception in command ascii_fonts:
Traceback (most recent call last):
  File "/usr/local/lib/python3.8/dist-packages/discord/ext/commands/core.py", line 85, in wrapped
    ret = await coro(*args, **kwargs)
  File "/root/bot/UMMBOT/cogs/utilitaire.py", line 41, in ascii_fonts
    await Ascii(self.client).ascii_fonts(ctx, *args)
  File "/root/bot/UMMBOT/utils/ascii_text.py", line 40, in ascii_fonts
    await channel.send(
  File "/usr/local/lib/python3.8/dist-packages/discord/abc.py", line 904, in send
    data = await state.http.send_message(channel.id, content, tts=tts, embed=embed,
  File "/usr/local/lib/python3.8/dist-packages/discord/http.py", line 245, in request
    raise HTTPException(r, data)
discord.errors.HTTPException: 400 Bad Request (error code: 50035): Invalid Form Body
In content: Must be 2000 or fewer in length.

The above exception was the direct cause of the following exception:

Traceback (most recent call last):
  File "/usr/local/lib/python3.8/dist-packages/discord/ext/commands/bot.py", line 903, in invoke
    await ctx.command.invoke(ctx)
  File "/usr/local/lib/python3.8/dist-packages/discord/ext/commands/core.py", line 859, in invoke
    await injected(*ctx.args, **ctx.kwargs)
  File "/usr/local/lib/python3.8/dist-packages/discord/ext/commands/core.py", line 94, in wrapped
    raise CommandInvokeError(exc) from exc
discord.ext.commands.errors.CommandInvokeError: Command raised an exception: HTTPException: 400 Bad Request (error code: 50035): Invalid Form Body
In content: Must be 2000 or fewer in length.
Vérification de la base de donnée...

Suppression de la commande help...
Effectué!

Génération des modules logs...
logs/messageEdit.py
Lancement du module messageEdit
logs/voiceConnection.py
Lancement du module voiceConnection
logs/guildChannelCreate.py
Lancement du module guildChannelCreate
logs/guildMemberJoin.py
Lancement du module guildMemberJoin
logs/guildRoleDelete.py
Lancement du module guildRoleDelete
logs/guildChannelDelete.py
Lancement du module guildChannelDelete
logs/messageAddReaction.py
Lancement du module messageAddReaction
logs/guildUserUpdate.py
Lancement du module guildUserUpdate
logs/voiceUpdate.py
Lancement du module voiceUpdate
logs/voiceSelfUpdate.py
Lancement du module voiceSelfUpdate
logs/messageRemoveReaction.py
Lancement du module messageRemoveReaction
logs/messageCreate.py
Lancement du module messageCreate
logs/guildRoleCreate.py
Lancement du module guildRoleCreate
logs/guildMemberLeave.py
Lancement du module guildMemberLeave
logs/messageDelete.py
Lancement du module messageDelete
logs/voiceSwitch.py
Lancement du module voiceSwitch
logs/guildMemberUpdate.py
Lancement du module guildMemberUpdate

Génération des modules commandes...
Lancement du module help_command
Lancement du module administration
Lancement du module utilitaire
Lancement du module moderation

Lancement du bot...
UMMBOT est prêt!
Lien d'invitation: https://discord.com/oauth2/authorize?client_id=677213520529457152&scope=bot&permissions=8

Pour inviter UMMBot, veillez copier ce lien et mettre au bot la permission administrateur.
Une fois rejoint, veillez déplacer le rôle UMMBot tout en haut de la liste des rôles.
En cas de problème, veillez contacter Bretzel_#2246.
Ignoring exception in command ascii_fonts:
Traceback (most recent call last):
  File "/usr/local/lib/python3.8/dist-packages/discord/ext/commands/core.py", line 85, in wrapped
    ret = await coro(*args, **kwargs)
  File "/root/bot/UMMBOT/cogs/utilitaire.py", line 43, in ascii_fonts
    await Ascii(self.client).ascii_fonts(ctx, *args)
  File "/root/bot/UMMBOT/utils/ascii_text.py", line 41, in ascii_fonts
    await channel.send(
  File "/usr/local/lib/python3.8/dist-packages/discord/abc.py", line 904, in send
    data = await state.http.send_message(channel.id, content, tts=tts, embed=embed,
  File "/usr/local/lib/python3.8/dist-packages/discord/http.py", line 245, in request
    raise HTTPException(r, data)
discord.errors.HTTPException: 400 Bad Request (error code: 50035): Invalid Form Body
In content: Must be 2000 or fewer in length.

The above exception was the direct cause of the following exception:

Traceback (most recent call last):
  File "/usr/local/lib/python3.8/dist-packages/discord/ext/commands/bot.py", line 903, in invoke
    await ctx.command.invoke(ctx)
  File "/usr/local/lib/python3.8/dist-packages/discord/ext/commands/core.py", line 859, in invoke
    await injected(*ctx.args, **ctx.kwargs)
  File "/usr/local/lib/python3.8/dist-packages/discord/ext/commands/core.py", line 94, in wrapped
    raise CommandInvokeError(exc) from exc
discord.ext.commands.errors.CommandInvokeError: Command raised an exception: HTTPException: 400 Bad Request (error code: 50035): Invalid Form Body
In content: Must be 2000 or fewer in length.
Vérification de la base de donnée...

Suppression de la commande help...
Effectué!

Génération des modules logs...
logs/messageEdit.py
Lancement du module messageEdit
logs/voiceConnection.py
Lancement du module voiceConnection
logs/guildChannelCreate.py
Lancement du module guildChannelCreate
logs/guildMemberJoin.py
Lancement du module guildMemberJoin
logs/guildRoleDelete.py
Lancement du module guildRoleDelete
logs/guildChannelDelete.py
Lancement du module guildChannelDelete
logs/messageAddReaction.py
Lancement du module messageAddReaction
logs/guildUserUpdate.py
Lancement du module guildUserUpdate
logs/voiceUpdate.py
Lancement du module voiceUpdate
logs/voiceSelfUpdate.py
Lancement du module voiceSelfUpdate
logs/messageRemoveReaction.py
Lancement du module messageRemoveReaction
logs/messageCreate.py
Lancement du module messageCreate
logs/guildRoleCreate.py
Lancement du module guildRoleCreate
logs/guildMemberLeave.py
Lancement du module guildMemberLeave
logs/messageDelete.py
Lancement du module messageDelete
logs/voiceSwitch.py
Lancement du module voiceSwitch
logs/guildMemberUpdate.py
Lancement du module guildMemberUpdate

Génération des modules commandes...
Lancement du module help_command
Lancement du module administration
Lancement du module utilitaire
Lancement du module moderation

Lancement du bot...
UMMBOT est prêt!
Lien d'invitation: https://discord.com/oauth2/authorize?client_id=677213520529457152&scope=bot&permissions=8

Pour inviter UMMBot, veillez copier ce lien et mettre au bot la permission administrateur.
Une fois rejoint, veillez déplacer le rôle UMMBot tout en haut de la liste des rôles.
En cas de problème, veillez contacter Bretzel_#2246.
Ignoring exception in command ascii_fonts:
Traceback (most recent call last):
  File "/root/bot/UMMBOT/utils/ascii_text.py", line 44, in ascii_fonts
    await channel.send(
  File "/usr/local/lib/python3.8/dist-packages/discord/abc.py", line 904, in send
    data = await state.http.send_message(channel.id, content, tts=tts, embed=embed,
  File "/usr/local/lib/python3.8/dist-packages/discord/http.py", line 178, in request
    await lock.acquire()
  File "/usr/lib/python3.8/asyncio/locks.py", line 203, in acquire
    await fut
asyncio.exceptions.CancelledError

During handling of the above exception, another exception occurred:

Traceback (most recent call last):
  File "/usr/local/lib/python3.8/dist-packages/discord/ext/commands/core.py", line 85, in wrapped
    ret = await coro(*args, **kwargs)
  File "/root/bot/UMMBOT/cogs/utilitaire.py", line 41, in ascii_fonts
    await Ascii(self.client).ascii_fonts(ctx, *args)
  File "/root/bot/UMMBOT/utils/ascii_text.py", line 47, in ascii_fonts
    await ctx.send("u noob")
  File "/usr/local/lib/python3.8/dist-packages/discord/abc.py", line 904, in send
    data = await state.http.send_message(channel.id, content, tts=tts, embed=embed,
  File "/usr/local/lib/python3.8/dist-packages/discord/http.py", line 185, in request
    async with self.__session.request(method, url, **kwargs) as r:
  File "/usr/local/lib/python3.8/dist-packages/aiohttp/client.py", line 1012, in __aenter__
    self._resp = await self._coro
  File "/usr/local/lib/python3.8/dist-packages/aiohttp/client.py", line 357, in _request
    raise RuntimeError('Session is closed')
RuntimeError: Session is closed

The above exception was the direct cause of the following exception:

Traceback (most recent call last):
  File "/usr/local/lib/python3.8/dist-packages/discord/ext/commands/bot.py", line 903, in invoke
    await ctx.command.invoke(ctx)
  File "/usr/local/lib/python3.8/dist-packages/discord/ext/commands/core.py", line 859, in invoke
    await injected(*ctx.args, **ctx.kwargs)
  File "/usr/local/lib/python3.8/dist-packages/discord/ext/commands/core.py", line 94, in wrapped
    raise CommandInvokeError(exc) from exc
discord.ext.commands.errors.CommandInvokeError: Command raised an exception: RuntimeError: Session is closed
Vérification de la base de donnée...

Suppression de la commande help...
Effectué!

Génération des modules logs...
logs/messageEdit.py
Lancement du module messageEdit
logs/voiceConnection.py
Lancement du module voiceConnection
logs/guildChannelCreate.py
Lancement du module guildChannelCreate
logs/guildMemberJoin.py
Lancement du module guildMemberJoin
logs/guildRoleDelete.py
Lancement du module guildRoleDelete
logs/guildChannelDelete.py
Lancement du module guildChannelDelete
logs/messageAddReaction.py
Lancement du module messageAddReaction
logs/guildUserUpdate.py
Lancement du module guildUserUpdate
logs/voiceUpdate.py
Lancement du module voiceUpdate
logs/voiceSelfUpdate.py
Lancement du module voiceSelfUpdate
logs/messageRemoveReaction.py
Lancement du module messageRemoveReaction
logs/messageCreate.py
Lancement du module messageCreate
logs/guildRoleCreate.py
Lancement du module guildRoleCreate
logs/guildMemberLeave.py
Lancement du module guildMemberLeave
logs/messageDelete.py
Lancement du module messageDelete
logs/voiceSwitch.py
Lancement du module voiceSwitch
logs/guildMemberUpdate.py
Lancement du module guildMemberUpdate

Génération des modules commandes...
Lancement du module help_command
Lancement du module administration
Lancement du module utilitaire
Lancement du module moderation

Lancement du bot...
UMMBOT est prêt!
Lien d'invitation: https://discord.com/oauth2/authorize?client_id=677213520529457152&scope=bot&permissions=8

Pour inviter UMMBot, veillez copier ce lien et mettre au bot la permission administrateur.
Une fois rejoint, veillez déplacer le rôle UMMBot tout en haut de la liste des rôles.
En cas de problème, veillez contacter Bretzel_#2246.
Vérification de la base de donnée...

Suppression de la commande help...
Effectué!

Génération des modules logs...
logs/messageEdit.py
Lancement du module messageEdit
logs/voiceConnection.py
Lancement du module voiceConnection
logs/guildChannelCreate.py
Lancement du module guildChannelCreate
logs/guildMemberJoin.py
Lancement du module guildMemberJoin
logs/guildRoleDelete.py
Lancement du module guildRoleDelete
logs/guildChannelDelete.py
Lancement du module guildChannelDelete
logs/messageAddReaction.py
Lancement du module messageAddReaction
logs/guildUserUpdate.py
Lancement du module guildUserUpdate
logs/voiceUpdate.py
Lancement du module voiceUpdate
logs/voiceSelfUpdate.py
Lancement du module voiceSelfUpdate
logs/messageRemoveReaction.py
Lancement du module messageRemoveReaction
logs/messageCreate.py
Lancement du module messageCreate
logs/guildRoleCreate.py
Lancement du module guildRoleCreate
logs/guildMemberLeave.py
Lancement du module guildMemberLeave
logs/messageDelete.py
Lancement du module messageDelete
logs/voiceSwitch.py
Lancement du module voiceSwitch
logs/guildMemberUpdate.py
Lancement du module guildMemberUpdate

Génération des modules commandes...
Lancement du module help_command
Lancement du module administration
Lancement du module utilitaire
Lancement du module moderation

Lancement du bot...
UMMBOT est prêt!
Lien d'invitation: https://discord.com/oauth2/authorize?client_id=677213520529457152&scope=bot&permissions=8

Pour inviter UMMBot, veillez copier ce lien et mettre au bot la permission administrateur.
Une fois rejoint, veillez déplacer le rôle UMMBot tout en haut de la liste des rôles.
En cas de problème, veillez contacter Bretzel_#2246.
2021-02-06 11:03:18,938 - WARNING - We are being rate limited. Retrying in 0.08 seconds. Handled under the bucket "697889935285289000:None:/channels/{channel_id}/messages/{message_id}/reactions/{emoji}/@me"
2021-02-06 11:03:21,058 - WARNING - We are being rate limited. Retrying in 0.08 seconds. Handled under the bucket "697889935285289000:None:/channels/{channel_id}/messages/{message_id}/reactions/{emoji}/@me"
2021-02-06 11:03:26,015 - WARNING - We are being rate limited. Retrying in 0.10 seconds. Handled under the bucket "697889935285289000:None:/channels/{channel_id}/messages/{message_id}/reactions/{emoji}/@me"
2021-02-06 11:03:35,892 - WARNING - We are being rate limited. Retrying in 0.09 seconds. Handled under the bucket "697889935285289000:None:/channels/{channel_id}/messages/{message_id}/reactions/{emoji}/@me"
2021-02-06 11:03:42,077 - WARNING - We are being rate limited. Retrying in 0.09 seconds. Handled under the bucket "697889935285289000:None:/channels/{channel_id}/messages/{message_id}/reactions/{emoji}/@me"
2021-02-06 11:03:52,159 - WARNING - We are being rate limited. Retrying in 0.11 seconds. Handled under the bucket "697889935285289000:None:/channels/{channel_id}/messages/{message_id}/reactions/{emoji}/@me"
2021-02-06 11:03:59,376 - WARNING - We are being rate limited. Retrying in 0.05 seconds. Handled under the bucket "697889935285289000:None:/channels/{channel_id}/messages/{message_id}/reactions/{emoji}/@me"
2021-02-06 11:04:04,821 - WARNING - We are being rate limited. Retrying in 0.04 seconds. Handled under the bucket "697889935285289000:None:/channels/{channel_id}/messages/{message_id}/reactions/{emoji}/@me"
2021-02-10 04:50:43,980 - ERROR - Attempting a reconnect in 1.74s
Traceback (most recent call last):
  File "/usr/local/lib/python3.8/dist-packages/discord/client.py", line 551, in connect
    await self.ws.poll_event()
  File "/usr/local/lib/python3.8/dist-packages/discord/gateway.py", line 587, in poll_event
    raise ConnectionClosed(self.socket, shard_id=self.shard_id, code=code) from None
discord.errors.ConnectionClosed: Shard ID None WebSocket closed with 1000
Ignoring exception in on_user_update
Traceback (most recent call last):
  File "/usr/local/lib/python3.8/dist-packages/discord/client.py", line 333, in _run_event
    await coro(*args, **kwargs)
  File "/root/bot/UMMBOT/logs/guildUserUpdate.py", line 43, in on_user_update
    guilds = cursor.fetchall()[0]
IndexError: list index out of range
2021-02-26 05:49:50,794 - ERROR - Attempting a reconnect in 0.38s
Traceback (most recent call last):
  File "/usr/local/lib/python3.8/dist-packages/discord/client.py", line 548, in connect
    self.ws = await asyncio.wait_for(coro, timeout=60.0)
  File "/usr/lib/python3.8/asyncio/tasks.py", line 501, in wait_for
    raise exceptions.TimeoutError()
asyncio.exceptions.TimeoutError
2021-03-11 16:31:06,912 - WARNING - We are being rate limited. Retrying in 0.10 seconds. Handled under the bucket "805060685641678912:None:/channels/{channel_id}/messages/{message_id}/reactions/{emoji}/@me"
2021-03-11 16:31:35,082 - WARNING - We are being rate limited. Retrying in 0.07 seconds. Handled under the bucket "805060685641678912:None:/channels/{channel_id}/messages/{message_id}/reactions/{emoji}/@me"
2021-03-11 16:31:43,086 - WARNING - We are being rate limited. Retrying in 0.09 seconds. Handled under the bucket "805060685641678912:None:/channels/{channel_id}/messages/{message_id}/reactions/{emoji}/@me"
2021-03-11 16:31:47,139 - WARNING - We are being rate limited. Retrying in 0.10 seconds. Handled under the bucket "805060685641678912:None:/channels/{channel_id}/messages/{message_id}/reactions/{emoji}/@me"
2021-03-11 16:31:51,621 - WARNING - We are being rate limited. Retrying in 0.07 seconds. Handled under the bucket "805060685641678912:None:/channels/{channel_id}/messages/{message_id}/reactions/{emoji}/@me"
2021-03-11 16:31:53,770 - WARNING - We are being rate limited. Retrying in 0.12 seconds. Handled under the bucket "805060685641678912:None:/channels/{channel_id}/messages/{message_id}/reactions/{emoji}/@me"
2021-03-15 19:36:34,269 - WARNING - We are being rate limited. Retrying in 0.07 seconds. Handled under the bucket "806284852130742293:None:/channels/{channel_id}/messages/{message_id}/reactions/{emoji}/@me"
Ignoring exception in command None:
discord.ext.commands.errors.CommandNotFound: Command "asciifonts" is not found
2021-03-24 02:22:06,219 - ERROR - Attempting a reconnect in 0.59s
Traceback (most recent call last):
  File "/usr/local/lib/python3.8/dist-packages/discord/client.py", line 551, in connect
    await self.ws.poll_event()
  File "/usr/local/lib/python3.8/dist-packages/discord/gateway.py", line 587, in poll_event
    raise ConnectionClosed(self.socket, shard_id=self.shard_id, code=code) from None
discord.errors.ConnectionClosed: Shard ID None WebSocket closed with 1000
Ignoring exception in on_user_update
Traceback (most recent call last):
  File "/usr/local/lib/python3.8/dist-packages/discord/client.py", line 333, in _run_event
    await coro(*args, **kwargs)
  File "/root/bot/UMMBOT/logs/guildUserUpdate.py", line 43, in on_user_update
    guilds = cursor.fetchall()[0]
IndexError: list index out of range
2021-05-14 18:03:32,388 - WARNING - We are being rate limited. Retrying in 0.09 seconds. Handled under the bucket "805107428672274442:None:/channels/{channel_id}/messages/{message_id}/reactions/{emoji}/@me"
2021-05-14 18:03:34,316 - WARNING - We are being rate limited. Retrying in 0.12 seconds. Handled under the bucket "805107428672274442:None:/channels/{channel_id}/messages/{message_id}/reactions/{emoji}/@me"
2021-05-14 18:03:39,133 - WARNING - We are being rate limited. Retrying in 0.11 seconds. Handled under the bucket "805107428672274442:None:/channels/{channel_id}/messages/{message_id}/reactions/{emoji}/@me"
Ignoring exception in on_user_update
Traceback (most recent call last):
  File "/usr/local/lib/python3.8/dist-packages/discord/client.py", line 333, in _run_event
    await coro(*args, **kwargs)
  File "/root/bot/UMMBOT/logs/guildUserUpdate.py", line 43, in on_user_update
    guilds = cursor.fetchall()[0]
IndexError: list index out of range
Ignoring exception in on_user_update
Traceback (most recent call last):
  File "/usr/local/lib/python3.8/dist-packages/discord/client.py", line 333, in _run_event
    await coro(*args, **kwargs)
  File "/root/bot/UMMBOT/logs/guildUserUpdate.py", line 43, in on_user_update
    guilds = cursor.fetchall()[0]
IndexError: list index out of range
Ignoring exception in on_user_update
Traceback (most recent call last):
  File "/usr/local/lib/python3.8/dist-packages/discord/client.py", line 333, in _run_event
    await coro(*args, **kwargs)
  File "/root/bot/UMMBOT/logs/guildUserUpdate.py", line 43, in on_user_update
    guilds = cursor.fetchall()[0]
IndexError: list index out of range
2021-06-24 22:36:57,339 - ERROR - Attempting a reconnect in 0.66s
Traceback (most recent call last):
  File "/usr/local/lib/python3.8/dist-packages/discord/client.py", line 548, in connect
    self.ws = await asyncio.wait_for(coro, timeout=60.0)
  File "/usr/lib/python3.8/asyncio/tasks.py", line 501, in wait_for
    raise exceptions.TimeoutError()
asyncio.exceptions.TimeoutError
2021-06-24 23:22:17,138 - ERROR - Attempting a reconnect in 1.55s
Traceback (most recent call last):
  File "/usr/local/lib/python3.8/dist-packages/discord/client.py", line 548, in connect
    self.ws = await asyncio.wait_for(coro, timeout=60.0)
  File "/usr/lib/python3.8/asyncio/tasks.py", line 501, in wait_for
    raise exceptions.TimeoutError()
asyncio.exceptions.TimeoutError
